<sdf version='1.11'>
  <model name='THex_Quadruped'>
    <link name='base_link'>
      <inertial>
        <pose>0.0001796 -0.0086064999999999996 0.035786999999999999 0 0 0</pose>
        <mass>0.30423</mass>
        <inertia>
          <ixx>0.00091370000000000004</ixx>
          <ixy>-2.1549000000000001e-07</ixy>
          <ixz>-8.2701000000000004e-07</ixz>
          <iyy>0.00019907</iyy>
          <iyz>-4.2938999999999997e-05</iyz>
          <izz>0.00074890999999999998</izz>
        </inertia>
      </inertial>
      <collision name='base_link_collision'>
        <pose>0 0 0 0 0 0</pose>
        <geometry>
          <mesh>
            <scale>1 1 1</scale>
            <uri>model://THex_Quadruped/meshes/base_link.STL</uri>
          </mesh>
        </geometry>
      </collision>
      <visual name='base_link_visual'>
        <pose>0 0 0 0 0 0</pose>
        <geometry>
          <mesh>
            <scale>1 1 1</scale>
            <uri>model://THex_Quadruped/meshes/base_link.STL</uri>
          </mesh>
        </geometry>
        <material>
          <diffuse>1 1 1 1</diffuse>
          <ambient>1 1 1 1</ambient>
        </material>
      </visual>
    </link>
    <joint name='bl_hip_joint' type='revolute'>
      <pose relative_to='base_link'>-0.053156000000000002 -0.12709000000000001 0 0 0 -2.3570000000000002</pose>
      <parent>base_link</parent>
      <child>bl_hip</child>
      <axis>
        <xyz>0 0 1</xyz>
        <limit>
          <lower>-0.7853</lower>
          <upper>0.7853</upper>
          <effort>0.9414</effort>
          <velocity>5.23</velocity>
        </limit>
        <dynamics>
          <spring_reference>0</spring_reference>
          <spring_stiffness>0</spring_stiffness>
        </dynamics>
      </axis>
    </joint>
    <link name='bl_hip'>
      <pose relative_to='bl_hip_joint'>0 0 0 0 0 0</pose>
      <inertial>
        <pose>0.0149715137794056 -0.0041788720385063198 0.012291206171491599 0 0 0</pose>
        <mass>0.080321429092671703</mass>
        <inertia>
          <ixx>1.9529275285755399e-05</ixx>
          <ixy>-3.7379120588045199e-07</ixy>
          <ixz>-3.73928570277161e-07</ixz>
          <iyy>1.26026628390034e-05</iyy>
          <iyz>-3.19588505184913e-08</iyz>
          <izz>1.2576278508053901e-05</izz>
        </inertia>
      </inertial>
      <collision name='bl_hip_collision'>
        <pose>0 0 0 0 0 0</pose>
        <geometry>
          <mesh>
            <scale>1 1 1</scale>
            <uri>model://THex_Quadruped/meshes/bl_hip.STL</uri>
          </mesh>
        </geometry>
      </collision>
      <visual name='bl_hip_visual'>
        <pose>0 0 0 0 0 0</pose>
        <geometry>
          <mesh>
            <scale>1 1 1</scale>
            <uri>model://THex_Quadruped/meshes/bl_hip.STL</uri>
          </mesh>
        </geometry>
        <material>
          <diffuse>1 1 1 1</diffuse>
          <ambient>1 1 1 1</ambient>
        </material>
      </visual>
    </link>
    <joint name='bl_knee_joint' type='revolute'>
      <pose relative_to='bl_hip'>0.028468 0 0 -1.5707 0 -0.071951000000000015</pose>
      <parent>bl_hip</parent>
      <child>bl_knee</child>
      <axis>
        <xyz>0 0 1</xyz>
        <limit>
          <lower>-1.5707</lower>
          <upper>1.5707</upper>
          <effort>0.9414</effort>
          <velocity>5.23</velocity>
        </limit>
        <dynamics>
          <spring_reference>0</spring_reference>
          <spring_stiffness>0</spring_stiffness>
        </dynamics>
      </axis>
    </joint>
    <link name='bl_knee'>
      <pose relative_to='bl_knee_joint'>0 0 0 0 0 0</pose>
      <inertial>
        <pose>0.045321399247135997 0.0044813673973086998 0.000153257653723683 0 0 0</pose>
        <mass>0.034681175593721698</mass>
        <inertia>
          <ixx>1.64563035522562e-05</ixx>
          <ixy>-9.8466945195644706e-07</ixy>
          <ixz>3.7671620551158402e-07</ixz>
          <iyy>2.0946363214089101e-05</iyy>
          <iyz>-4.8191602779166402e-08</iyz>
          <izz>9.0589553267295096e-06</izz>
        </inertia>
      </inertial>
      <collision name='bl_knee_collision'>
        <pose>0 0 0 0 0 0</pose>
        <geometry>
          <mesh>
            <scale>1 1 1</scale>
            <uri>model://THex_Quadruped/meshes/bl_knee.STL</uri>
          </mesh>
        </geometry>
      </collision>
      <visual name='bl_knee_visual'>
        <pose>0 0 0 0 0 0</pose>
        <geometry>
          <mesh>
            <scale>1 1 1</scale>
            <uri>model://THex_Quadruped/meshes/bl_knee.STL</uri>
          </mesh>
        </geometry>
        <material>
          <diffuse>1 1 1 1</diffuse>
          <ambient>1 1 1 1</ambient>
        </material>
      </visual>
    </link>
    <joint name='bl_foot_joint' type='revolute'>
      <pose relative_to='bl_knee'>0.072935 0.018648999999999999 0 3.1415 0 0.7853</pose>
      <parent>bl_knee</parent>
      <child>bl_foot</child>
      <axis>
        <xyz>0 0 1</xyz>
        <limit>
          <lower>-1.5707</lower>
          <upper>1.5707</upper>
          <effort>0.9414</effort>
          <velocity>5.23</velocity>
        </limit>
        <dynamics>
          <spring_reference>0</spring_reference>
          <spring_stiffness>0</spring_stiffness>
        </dynamics>
      </axis>
    </joint>
    <link name='bl_foot'>
      <pose relative_to='bl_foot_joint'>0 0 0 0 0 0</pose>
      <inertial>
        <pose>0.021140907524691499 0.0035784863304674499 -5.75329770011457e-05 0 0 0</pose>
        <mass>0.057594735109815803</mass>
        <inertia>
          <ixx>6.4442397488172799e-06</ixx>
          <ixy>3.9437115474232502e-07</ixy>
          <ixz>6.5940986778231197e-08</ixz>
          <iyy>1.1704696508681e-05</iyy>
          <iyz>-3.8043766979809302e-07</iyz>
          <izz>9.2665178963128599e-06</izz>
        </inertia>
      </inertial>
      <collision name='bl_foot_collision'>
        <pose>0 0 0 0 0 0</pose>
        <geometry>
          <mesh>
            <scale>1 1 1</scale>
            <uri>model://THex_Quadruped/meshes/bl_foot.STL</uri>
          </mesh>
        </geometry>
      </collision>
      <visual name='bl_foot_visual'>
        <pose>0 0 0 0 0 0</pose>
        <geometry>
          <mesh>
            <scale>1 1 1</scale>
            <uri>model://THex_Quadruped/meshes/bl_foot.STL</uri>
          </mesh>
        </geometry>
        <material>
          <diffuse>1 1 1 1</diffuse>
          <ambient>1 1 1 1</ambient>
        </material>
      </visual>
    </link>
    <joint name='br_hip_joint' type='revolute'>
      <pose relative_to='base_link'>0.053156000000000002 -0.12709000000000001 0 0 0 -0.78456000000000026</pose>
      <parent>base_link</parent>
      <child>br_hip</child>
      <axis>
        <xyz>0 0 1</xyz>
        <limit>
          <lower>-0.7853</lower>
          <upper>0.7853</upper>
          <effort>0.9414</effort>
          <velocity>5.23</velocity>
        </limit>
        <dynamics>
          <spring_reference>0</spring_reference>
          <spring_stiffness>0</spring_stiffness>
        </dynamics>
      </axis>
    </joint>
    <link name='br_hip'>
      <pose relative_to='br_hip_joint'>0 0 0 0 0 0</pose>
      <inertial>
        <pose>0.0149713908034494 0.0038231832167566599 0.011963761614816401 0 0 0</pose>
        <mass>0.080321429096474606</mass>
        <inertia>
          <ixx>1.9529275286071501e-05</ixx>
          <ixy>3.7325815615006197e-07</ixy>
          <ixz>-3.7344784318272402e-07</ixz>
          <iyy>1.26026653190317e-05</iyy>
          <iyz>3.7625759856745598e-08</iyz>
          <izz>1.2576276027723999e-05</izz>
        </inertia>
      </inertial>
      <collision name='br_hip_collision'>
        <pose>0 0 0 0 0 0</pose>
        <geometry>
          <mesh>
            <scale>1 1 1</scale>
            <uri>model://THex_Quadruped/meshes/br_hip.STL</uri>
          </mesh>
        </geometry>
      </collision>
      <visual name='br_hip_visual'>
        <pose>0 0 0 0 0 0</pose>
        <geometry>
          <mesh>
            <scale>1 1 1</scale>
            <uri>model://THex_Quadruped/meshes/br_hip.STL</uri>
          </mesh>
        </geometry>
        <material>
          <diffuse>1 1 1 1</diffuse>
          <ambient>1 1 1 1</ambient>
        </material>
      </visual>
    </link>
    <joint name='br_knee_joint' type='revolute'>
      <pose relative_to='br_hip'>0.028468 0 0 1.5707 0 0</pose>
      <parent>br_hip</parent>
      <child>br_knee</child>
      <axis>
        <xyz>0 0 1</xyz>
        <limit>
          <lower>-1.5707</lower>
          <upper>1.5707</upper>
          <effort>0.9414</effort>
          <velocity>5.23</velocity>
        </limit>
        <dynamics>
          <spring_reference>0</spring_reference>
          <spring_stiffness>0</spring_stiffness>
        </dynamics>
      </axis>
    </joint>
    <link name='br_knee'>
      <pose relative_to='br_knee_joint'>0 0 0 0 0 0</pose>
      <inertial>
        <pose>0.045299153786559999 -0.0044813671280395104 0.00016244919069483701 0 0 0</pose>
        <mass>0.0346811755975251</mass>
        <inertia>
          <ixx>1.6464020982287698e-05</ixx>
          <ixy>9.8516055417118595e-07</ixy>
          <ixz>2.9114831182612301e-07</ixz>
          <iyy>2.0946363174086499e-05</iyy>
          <iyz>3.6810992473478999e-08</iyz>
          <izz>9.0512379367159099e-06</izz>
        </inertia>
      </inertial>
      <collision name='br_knee_collision'>
        <pose>0 0 0 0 0 0</pose>
        <geometry>
          <mesh>
            <scale>1 1 1</scale>
            <uri>model://THex_Quadruped/meshes/br_knee.STL</uri>
          </mesh>
        </geometry>
      </collision>
      <visual name='br_knee_visual'>
        <pose>0 0 0 0 0 0</pose>
        <geometry>
          <mesh>
            <scale>1 1 1</scale>
            <uri>model://THex_Quadruped/meshes/br_knee.STL</uri>
          </mesh>
        </geometry>
        <material>
          <diffuse>1 1 1 1</diffuse>
          <ambient>1 1 1 1</ambient>
        </material>
      </visual>
    </link>
    <joint name='br_foot_joint' type='revolute'>
      <pose relative_to='br_knee'>0.072955999999999993 -0.018648999999999999 0 -3.1415 0 -0.7853</pose>
      <parent>br_knee</parent>
      <child>br_foot</child>
      <axis>
        <xyz>0 0 1</xyz>
        <limit>
          <lower>-1.5707</lower>
          <upper>1.5707</upper>
          <effort>0.9414</effort>
          <velocity>5.23</velocity>
        </limit>
        <dynamics>
          <spring_reference>0</spring_reference>
          <spring_stiffness>0</spring_stiffness>
        </dynamics>
      </axis>
    </joint>
    <link name='br_foot'>
      <pose relative_to='br_foot_joint'>0 0 0 0 0 0</pose>
      <inertial>
        <pose>0.020855637795625898 -0.0035806485840898499 -5.4412617953761302e-05 0 0 0</pose>
        <mass>0.057594735109815803</mass>
        <inertia>
          <ixx>6.4444144866108199e-06</ixx>
          <ixy>-3.9421451037638098e-07</ixy>
          <ixz>6.9067314932633799e-08</ixz>
          <iyy>1.1704646492118901e-05</iyy>
          <iyz>3.8052028087382701e-07</iyz>
          <izz>9.2663931750813908e-06</izz>
        </inertia>
      </inertial>
      <collision name='br_foot_collision'>
        <pose>0 0 0 0 0 0</pose>
        <geometry>
          <mesh>
            <scale>1 1 1</scale>
            <uri>model://THex_Quadruped/meshes/br_foot.STL</uri>
          </mesh>
        </geometry>
      </collision>
      <visual name='br_foot_visual'>
        <pose>0 0 0 0 0 0</pose>
        <geometry>
          <mesh>
            <scale>1 1 1</scale>
            <uri>model://THex_Quadruped/meshes/br_foot.STL</uri>
          </mesh>
        </geometry>
        <material>
          <diffuse>1 1 1 1</diffuse>
          <ambient>1 1 1 1</ambient>
        </material>
      </visual>
    </link>
    <joint name='fl_hip_joint' type='revolute'>
      <pose relative_to='base_link'>-0.059506000000000003 0.078833 0 0 0 2.3570000000000002</pose>
      <parent>base_link</parent>
      <child>fl_hip</child>
      <axis>
        <xyz>0 0 1</xyz>
        <limit>
          <lower>-0.7853</lower>
          <upper>0.7853</upper>
          <effort>0.9414</effort>
          <velocity>5.23</velocity>
        </limit>
        <dynamics>
          <spring_reference>0</spring_reference>
          <spring_stiffness>0</spring_stiffness>
        </dynamics>
      </axis>
    </joint>
    <link name='fl_hip'>
      <pose relative_to='fl_hip_joint'>0 0 0 0 0 0</pose>
      <inertial>
        <pose>0.0149716247702561 0.0057777451089918198 0.012291613219433801 0 0 0</pose>
        <mass>0.080321429096442798</mass>
        <inertia>
          <ixx>1.9529275286079799e-05</ixx>
          <ixy>-3.73954665015097e-07</ixy>
          <ixz>-3.73764931109102e-07</ixz>
          <iyy>1.2602650088420399e-05</iyy>
          <iyz>2.8277918763949599e-09</iyz>
          <izz>1.2576291258326499e-05</izz>
        </inertia>
      </inertial>
      <collision name='fl_hip_collision'>
        <pose>0 0 0 0 0 0</pose>
        <geometry>
          <mesh>
            <scale>1 1 1</scale>
            <uri>model://THex_Quadruped/meshes/fl_hip.STL</uri>
          </mesh>
        </geometry>
      </collision>
      <visual name='fl_hip_visual'>
        <pose>0 0 0 0 0 0</pose>
        <geometry>
          <mesh>
            <scale>1 1 1</scale>
            <uri>model://THex_Quadruped/meshes/fl_hip.STL</uri>
          </mesh>
        </geometry>
        <material>
          <diffuse>1 1 1 1</diffuse>
          <ambient>1 1 1 1</ambient>
        </material>
      </visual>
    </link>
    <joint name='fl_knee_joint' type='revolute'>
      <pose relative_to='fl_hip'>0.028468 0 0 -1.5707 0 0</pose>
      <parent>fl_hip</parent>
      <child>fl_knee</child>
      <axis>
        <xyz>0 0 1</xyz>
        <limit>
          <lower>-1.5707</lower>
          <upper>1.5707</upper>
          <effort>0.9414</effort>
          <velocity>5.23</velocity>
        </limit>
        <dynamics>
          <spring_reference>0</spring_reference>
          <spring_stiffness>0</spring_stiffness>
        </dynamics>
      </axis>
    </joint>
    <link name='fl_knee'>
      <pose relative_to='fl_knee_joint'>0 0 0 0 0 0</pose>
      <inertial>
        <pose>0.045270903487398498 0.0044813535834028499 0.00019220441685056201 0 0 0</pose>
        <mass>0.034681175597501397</mass>
        <inertia>
          <ixx>1.6475454333389701e-05</ixx>
          <ixy>-9.8592639914781392e-07</ixy>
          <ixz>1.1849488598333e-08</ixz>
          <iyy>2.09463286427022e-05</iyy>
          <iyz>2.5070321661832802e-10</iyz>
          <izz>9.0398391169982396e-06</izz>
        </inertia>
      </inertial>
      <collision name='fl_knee_collision'>
        <pose>0 0 0 0 0 0</pose>
        <geometry>
          <mesh>
            <scale>1 1 1</scale>
            <uri>model://THex_Quadruped/meshes/fl_knee.STL</uri>
          </mesh>
        </geometry>
      </collision>
      <visual name='fl_knee_visual'>
        <pose>0 0 0 0 0 0</pose>
        <geometry>
          <mesh>
            <scale>1 1 1</scale>
            <uri>model://THex_Quadruped/meshes/fl_knee.STL</uri>
          </mesh>
        </geometry>
        <material>
          <diffuse>1 1 1 1</diffuse>
          <ambient>1 1 1 1</ambient>
        </material>
      </visual>
    </link>
    <joint name='fl_foot_joint' type='revolute'>
      <pose relative_to='fl_knee'>0.073042999999999997 0.018648999999999999 0 3.1415 0 0.7853</pose>
      <parent>fl_knee</parent>
      <child>fl_foot</child>
      <axis>
        <xyz>0 0 1</xyz>
        <limit>
          <lower>-1.5707</lower>
          <upper>1.5707</upper>
          <effort>0.9414</effort>
          <velocity>5.23</velocity>
        </limit>
        <dynamics>
          <spring_reference>0</spring_reference>
          <spring_stiffness>0</spring_stiffness>
        </dynamics>
      </axis>
    </joint>
    <link name='fl_foot'>
      <pose relative_to='fl_foot_joint'>0 0 0 0 0 0</pose>
      <inertial>
        <pose>0.0211409047516125 0.0035784866490062 -5.7534049239305099e-05 0 0 0</pose>
        <mass>0.057594735109968903</mass>
        <inertia>
          <ixx>6.4442397599178703e-06</ixx>
          <ixy>3.9437152659864401e-07</ixy>
          <ixz>6.5941028995855197e-08</ixz>
          <iyy>1.17046964965352e-05</iyy>
          <iyz>-3.8043666234120398e-07</iyz>
          <izz>9.2665178973581206e-06</izz>
        </inertia>
      </inertial>
      <collision name='fl_foot_collision'>
        <pose>0 0 0 0 0 0</pose>
        <geometry>
          <mesh>
            <scale>1 1 1</scale>
            <uri>model://THex_Quadruped/meshes/fl_foot.STL</uri>
          </mesh>
        </geometry>
      </collision>
      <visual name='fl_foot_visual'>
        <pose>0 0 0 0 0 0</pose>
        <geometry>
          <mesh>
            <scale>1 1 1</scale>
            <uri>model://THex_Quadruped/meshes/fl_foot.STL</uri>
          </mesh>
        </geometry>
        <material>
          <diffuse>1 1 1 1</diffuse>
          <ambient>1 1 1 1</ambient>
        </material>
      </visual>
    </link>
    <joint name='fr_hip_joint' type='revolute'>
      <pose relative_to='base_link'>0.059506000000000003 0.078833 0 0 0 0.78456000000000026</pose>
      <parent>base_link</parent>
      <child>fr_hip</child>
      <axis>
        <xyz>0 0 1</xyz>
        <limit>
          <lower>-0.7853</lower>
          <upper>0.7853</upper>
          <effort>0.9414</effort>
          <velocity>5.23</velocity>
        </limit>
        <dynamics>
          <spring_reference>0</spring_reference>
          <spring_stiffness>0</spring_stiffness>
        </dynamics>
      </axis>
    </joint>
    <link name='fr_hip'>
      <pose relative_to='fr_hip_joint'>0 0 0 0 0 0</pose>
      <inertial>
        <pose>0.014971391187940599 -0.0061335240800283498 0.0119642464258807 0 0 0</pose>
        <mass>0.080321429092621605</mass>
        <inertia>
          <ixx>1.95292752857998e-05</ixx>
          <ixy>3.7342156881172701e-07</ixy>
          <ixz>-3.7323201148671202e-07</ixz>
          <iyy>1.2602647608356e-05</iyy>
          <iyz>2.8391174471058502e-09</iyz>
          <izz>1.2576293738656401e-05</izz>
        </inertia>
      </inertial>
      <collision name='fr_hip_collision'>
        <pose>0 0 0 0 0 0</pose>
        <geometry>
          <mesh>
            <scale>1 1 1</scale>
            <uri>model://THex_Quadruped/meshes/fr_hip.STL</uri>
          </mesh>
        </geometry>
      </collision>
      <visual name='fr_hip_visual'>
        <pose>0 0 0 0 0 0</pose>
        <geometry>
          <mesh>
            <scale>1 1 1</scale>
            <uri>model://THex_Quadruped/meshes/fr_hip.STL</uri>
          </mesh>
        </geometry>
        <material>
          <diffuse>1 1 1 1</diffuse>
          <ambient>1 1 1 1</ambient>
        </material>
      </visual>
    </link>
    <joint name='fr_knee_joint' type='revolute'>
      <pose relative_to='fr_hip'>0.028468 0 0 1.5707 0 0</pose>
      <parent>fr_hip</parent>
      <child>fr_knee</child>
      <axis>
        <xyz>0 0 1</xyz>
        <limit>
          <lower>-1.5707</lower>
          <upper>1.5707</upper>
          <effort>0.9414</effort>
          <velocity>5.23</velocity>
        </limit>
        <dynamics>
          <spring_reference>0</spring_reference>
          <spring_stiffness>0</spring_stiffness>
        </dynamics>
      </axis>
    </joint>
    <link name='fr_knee'>
      <pose relative_to='fr_knee_joint'>0 0 0 0 0 0</pose>
      <inertial>
        <pose>0.045275477631185397 -0.0044813504878377696 0.00020131850571926399 0 0 0</pose>
        <mass>0.034681175593659297</mass>
        <inertia>
          <ixx>1.6474738360218702e-05</ixx>
          <ixy>9.85873389394324e-07</ixy>
          <ixz>-7.4273037405926797e-08</ixz>
          <iyy>2.09463215295828e-05</iyy>
          <iyz>-1.16706155416745e-08</iyz>
          <izz>9.0405622032733796e-06</izz>
        </inertia>
      </inertial>
      <collision name='fr_knee_collision'>
        <pose>0 0 0 0 0 0</pose>
        <geometry>
          <mesh>
            <scale>1 1 1</scale>
            <uri>model://THex_Quadruped/meshes/fr_knee.STL</uri>
          </mesh>
        </geometry>
      </collision>
      <visual name='fr_knee_visual'>
        <pose>0 0 0 0 0 0</pose>
        <geometry>
          <mesh>
            <scale>1 1 1</scale>
            <uri>model://THex_Quadruped/meshes/fr_knee.STL</uri>
          </mesh>
        </geometry>
        <material>
          <diffuse>1 1 1 1</diffuse>
          <ambient>1 1 1 1</ambient>
        </material>
      </visual>
    </link>
    <joint name='fr_foot_joint' type='revolute'>
      <pose relative_to='fr_knee'>0.073075000000000001 -0.018648999999999999 0 3.1415 0 -0.7853</pose>
      <parent>fr_knee</parent>
      <child>fr_foot</child>
      <axis>
        <xyz>0 0 1</xyz>
        <limit>
          <lower>-1.5707</lower>
          <upper>1.5707</upper>
          <effort>0.9414</effort>
          <velocity>5.23</velocity>
        </limit>
        <dynamics>
          <spring_reference>0</spring_reference>
          <spring_stiffness>0</spring_stiffness>
        </dynamics>
      </axis>
    </joint>
    <link name='fr_foot'>
      <pose relative_to='fr_foot_joint'>0 0 0 0 0 0</pose>
      <inertial>
        <pose>0.020855640524371701 -0.0035806482652497602 -5.44138222527413e-05 0 0 0</pose>
        <mass>0.0575947351098159</mass>
        <inertia>
          <ixx>6.4444144787463799e-06</ixx>
          <ixy>-3.94214177966817e-07</ixy>
          <ixz>6.9067357279190904e-08</ixz>
          <iyy>1.17046465010787e-05</iyy>
          <iyz>3.8051925925168301e-07</iyz>
          <izz>9.2663931739860603e-06</izz>
        </inertia>
      </inertial>
      <collision name='fr_foot_collision'>
        <pose>0 0 0 0 0 0</pose>
        <geometry>
          <mesh>
            <scale>1 1 1</scale>
            <uri>model://THex_Quadruped/meshes/fr_foot.STL</uri>
          </mesh>
        </geometry>
      </collision>
      <visual name='fr_foot_visual'>
        <pose>0 0 0 0 0 0</pose>
        <geometry>
          <mesh>
            <scale>1 1 1</scale>
            <uri>model://THex_Quadruped/meshes/fr_foot.STL</uri>
          </mesh>
        </geometry>
        <material>
          <diffuse>1 1 1 1</diffuse>
          <ambient>1 1 1 1</ambient>
        </material>
      </visual>
    </link>
    <plugin name="gz::sim::systems::JointPositionController" filename="libgz-sim-joint-position-controller-system.so">
  	<joint_name>fr_hip_joint</joint_name>
    </plugin>
    <plugin name="gz::sim::systems::JointPositionController" filename="libgz-sim-joint-position-controller-system.so">
  	<joint_name>fr_knee_joint</joint_name>
    </plugin>
    <plugin name="gz::sim::systems::JointPositionController" filename="libgz-sim-joint-position-controller-system.so">
  	<joint_name>fr_foot_joint</joint_name>
    </plugin>
    <plugin name="gz::sim::systems::JointPositionController" filename="libgz-sim-joint-position-controller-system.so">
  	<joint_name>fl_hip_joint</joint_name>
    </plugin>
    <plugin name="gz::sim::systems::JointPositionController" filename="libgz-sim-joint-position-controller-system.so">
  	<joint_name>fl_knee_joint</joint_name>
    </plugin>
    <plugin name="gz::sim::systems::JointPositionController" filename="libgz-sim-joint-position-controller-system.so">
  	<joint_name>fl_foot_joint</joint_name>
    </plugin>
    <plugin name="gz::sim::systems::JointPositionController" filename="libgz-sim-joint-position-controller-system.so">
  	<joint_name>bl_hip_joint</joint_name>
    </plugin>
    <plugin name="gz::sim::systems::JointPositionController" filename="libgz-sim-joint-position-controller-system.so">
  	<joint_name>bl_knee_joint</joint_name>
    </plugin>
    <plugin name="gz::sim::systems::JointPositionController" filename="libgz-sim-joint-position-controller-system.so">
  	<joint_name>bl_foot_joint</joint_name>
    </plugin>
    <plugin name="gz::sim::systems::JointPositionController" filename="libgz-sim-joint-position-controller-system.so">
  	<joint_name>br_hip_joint</joint_name>
    </plugin>
    <plugin name="gz::sim::systems::JointPositionController" filename="libgz-sim-joint-position-controller-system.so">
  	<joint_name>br_knee_joint</joint_name>
    </plugin>
    <plugin name="gz::sim::systems::JointPositionController" filename="libgz-sim-joint-position-controller-system.so">
  	<joint_name>br_foot_joint</joint_name>
    </plugin>
  </model>
</sdf>
