<sdf version='1.11'>
  <model name='THex_Quadruped'>
    <link name='base_link'>
      <inertial>
        <pose>-1.0171e-10 -0.0086064999999999996 0.036080000000000001 0 0 0</pose>
        <mass>0.30423</mass>
        <inertia>
          <ixx>0.00091370000000000004</ixx>
          <ixy>-1.0719e-13</ixy>
          <ixz>3.2475999999999998e-14</ixz>
          <iyy>0.00019907</iyy>
          <iyz>-4.2938999999999997e-05</iyz>
          <izz>0.00074890999999999998</izz>
        </inertia>
      </inertial>
      <collision name='base_link_collision'>
        <pose>0 0 0 0 0 0</pose>
        <geometry>
          <mesh>
            <scale>1 1 1</scale>
            <uri>model://THex_Quadruped/meshes/base_link_collision.STL</uri>
          </mesh>
        </geometry>
      </collision>
      <visual name='base_link_visual'>
        <pose>0 0 0 0 0 0</pose>
        <geometry>
          <mesh>
            <scale>1 1 1</scale>
            <uri>model://THex_Quadruped/meshes/base_link.STL</uri>
          </mesh>
        </geometry>
        <material>
          <diffuse>1 1 1 1</diffuse>
          <ambient>1 1 1 1</ambient>
        </material>
      </visual>
    </link>
    <joint name='bl_hip_joint' type='revolute'>
      <pose relative_to='base_link'>-0.053162000000000001 -0.12711 0 0 0 -2.3719999999999999</pose>
      <parent>base_link</parent>
      <child>bl_hip</child>
      <axis>
        <xyz>0 0 1</xyz>
        <limit>
          <lower>-0.7853</lower>
          <upper>0.7853</upper>
          <effort>0.94140000000000001</effort>
          <velocity>5.2300000000000004</velocity>
        </limit>
        <dynamics>
          <spring_reference>0</spring_reference>
          <spring_stiffness>0</spring_stiffness>
        </dynamics>
      </axis>
    </joint>
    <link name='bl_hip'>
      <pose relative_to='bl_hip_joint'>0 0 0 0 0 0</pose>
      <inertial>
        <pose>0.015013 -0.0039617999999999997 0.012298999999999999 0 0 0</pose>
        <mass>0.080321000000000004</mass>
        <inertia>
          <ixx>1.9539e-05</ixx>
          <ixy>-2.7001999999999998e-07</ixy>
          <ixz>-3.7333000000000002e-07</ixz>
          <iyy>1.2593e-05</iyy>
          <iyz>-3.7557999999999998e-08</iyz>
          <izz>1.2576e-05</izz>
        </inertia>
      </inertial>
      <collision name='bl_hip_collision'>
        <pose>0 0 0 0 0 0</pose>
        <geometry>
          <mesh>
            <scale>1 1 1</scale>
            <uri>model://THex_Quadruped/meshes/bl_hip_collision.STL</uri>
          </mesh>
        </geometry>
      </collision>
      <visual name='bl_hip_visual'>
        <pose>0 0 0 0 0 0</pose>
        <geometry>
          <mesh>
            <scale>1 1 1</scale>
            <uri>model://THex_Quadruped/meshes/bl_hip.STL</uri>
          </mesh>
        </geometry>
        <material>
          <diffuse>1 1 1 1</diffuse>
          <ambient>1 1 1 1</ambient>
        </material>
      </visual>
    </link>
    <joint name='bl_knee_joint' type='revolute'>
      <pose relative_to='bl_hip'>0.028451000000000001 0 0 -1.5602 -0.78534000000000004 -7.8500057236944626e-17</pose>
      <parent>bl_hip</parent>
      <child>bl_knee</child>
      <axis>
        <xyz>0.010586999999999999 0 -0.99994000000000005</xyz>
        <limit>
          <lower>-1.5707</lower>
          <upper>1.5707</upper>
          <effort>0.94140000000000001</effort>
          <velocity>5.2300000000000004</velocity>
        </limit>
        <dynamics>
          <spring_reference>0</spring_reference>
          <spring_stiffness>0</spring_stiffness>
        </dynamics>
      </axis>
    </joint>
    <link name='bl_knee'>
      <pose relative_to='bl_knee_joint'>0 0 0 0 0 0</pose>
      <inertial>
        <pose>0.045290999999999998 0.0044812999999999997 -0.0012523 0 0 0</pose>
        <mass>0.034680999999999997</mass>
        <inertia>
          <ixx>1.6475000000000001e-05</ixx>
          <ixy>-9.8627e-07</ixy>
          <ixz>7.8716000000000002e-08</ixz>
          <iyy>2.0945999999999999e-05</iyy>
          <iyz>-1.0442e-08</iyz>
          <izz>9.0406999999999997e-06</izz>
        </inertia>
      </inertial>
      <collision name='bl_knee_collision'>
        <pose>0 0 0 0 0 0</pose>
        <geometry>
          <mesh>
            <scale>1 1 1</scale>
            <uri>model://THex_Quadruped/meshes/bl_knee_collision.STL</uri>
          </mesh>
        </geometry>
      </collision>
      <visual name='bl_knee_visual'>
        <pose>0 0 0 0 0 0</pose>
        <geometry>
          <mesh>
            <scale>1 1 1</scale>
            <uri>model://THex_Quadruped/meshes/bl_knee.STL</uri>
          </mesh>
        </geometry>
        <material>
          <diffuse>1 1 1 1</diffuse>
          <ambient>1 1 1 1</ambient>
        </material>
      </visual>
    </link>
    <joint name='bl_foot_joint' type='revolute'>
      <pose relative_to='bl_knee'>0.073068999999999995 0.018655999999999999 -0.00019751 3.1339999999999999 0.0073895000000000054 2.3433999999999999</pose>
      <parent>bl_knee</parent>
      <child>bl_foot</child>
      <axis>
        <xyz>0 0 1</xyz>
        <limit>
          <lower>-1.5707</lower>
          <upper>1.5707</upper>
          <effort>0.94140000000000001</effort>
          <velocity>5.2300000000000004</velocity>
        </limit>
        <dynamics>
          <spring_reference>0</spring_reference>
          <spring_stiffness>0</spring_stiffness>
        </dynamics>
      </axis>
    </joint>
    <link name='bl_foot'>
      <pose relative_to='bl_foot_joint'>0 0 0 0 0 0</pose>
      <inertial>
        <pose>0.021142000000000001 0.0035788 -0.0013921000000000001 0 0 0</pose>
        <mass>0.057595</mass>
        <inertia>
          <ixx>6.4423000000000001e-06</ixx>
          <ixy>3.9845000000000002e-07</ixy>
          <ixz>1.1196e-08</ixz>
          <iyy>1.1705000000000001e-05</iyy>
          <iyz>-3.7378e-07</iyz>
          <izz>9.2683000000000007e-06</izz>
        </inertia>
      </inertial>
      <collision name='bl_foot_collision'>
        <pose>0 0 0 0 0 0</pose>
        <geometry>
          <mesh>
            <scale>1 1 1</scale>
            <uri>model://THex_Quadruped/meshes/bl_foot_collision.STL</uri>
          </mesh>
        </geometry>
      </collision>
      <visual name='bl_foot_visual'>
        <pose>0 0 0 0 0 0</pose>
        <geometry>
          <mesh>
            <scale>1 1 1</scale>
            <uri>model://THex_Quadruped/meshes/bl_foot.STL</uri>
          </mesh>
        </geometry>
        <material>
          <diffuse>1 1 1 1</diffuse>
          <ambient>1 1 1 1</ambient>
        </material>
      </visual>
    </link>
    <joint name='br_hip_joint' type='revolute'>
      <pose relative_to='base_link'>0.053162000000000001 -0.12711 0.00053339999999999995 0 0 -0.77529000000000003</pose>
      <parent>base_link</parent>
      <child>br_hip</child>
      <axis>
        <xyz>0 0 1</xyz>
        <limit>
          <lower>-0.7853</lower>
          <upper>0.7853</upper>
          <effort>0.94140000000000001</effort>
          <velocity>5.2300000000000004</velocity>
        </limit>
        <dynamics>
          <spring_reference>0</spring_reference>
          <spring_stiffness>0</spring_stiffness>
        </dynamics>
      </axis>
    </joint>
    <link name='br_hip'>
      <pose relative_to='br_hip_joint'>0 0 0 0 0 0</pose>
      <inertial>
        <pose>0.014987 0.0036917999999999999 0.011971000000000001 0 0 0</pose>
        <mass>0.080321000000000004</mass>
        <inertia>
          <ixx>1.9536000000000001e-05</ixx>
          <ixy>3.0917000000000001e-07</ixy>
          <ixz>-3.7300000000000002e-07</ixz>
          <iyy>1.2595999999999999e-05</iyy>
          <iyz>4.1086000000000001e-08</iyz>
          <izz>1.2576e-05</izz>
        </inertia>
      </inertial>
      <collision name='br_hip_collision'>
        <pose>0 0 0 0 0 0</pose>
        <geometry>
          <mesh>
            <scale>1 1 1</scale>
            <uri>model://THex_Quadruped/meshes/br_hip_collision.STL</uri>
          </mesh>
        </geometry>
      </collision>
      <visual name='br_hip_visual'>
        <pose>0 0 0 0 0 0</pose>
        <geometry>
          <mesh>
            <scale>1 1 1</scale>
            <uri>model://THex_Quadruped/meshes/br_hip.STL</uri>
          </mesh>
        </geometry>
        <material>
          <diffuse>1 1 1 1</diffuse>
          <ambient>1 1 1 1</ambient>
        </material>
      </visual>
    </link>
    <joint name='br_knee_joint' type='revolute'>
      <pose relative_to='br_hip'>0.028448999999999999 0 0 1.5643 -0.78537999999999997 0</pose>
      <parent>br_hip</parent>
      <child>br_knee</child>
      <axis>
        <xyz>0.0065446999999999996 0 -0.99997999999999998</xyz>
        <limit>
          <lower>-1.5707</lower>
          <upper>1.5707</upper>
          <effort>0.94140000000000001</effort>
          <velocity>5.2300000000000004</velocity>
        </limit>
        <dynamics>
          <spring_reference>0</spring_reference>
          <spring_stiffness>0</spring_stiffness>
        </dynamics>
      </axis>
    </joint>
    <link name='br_knee'>
      <pose relative_to='br_knee_joint'>0 0 0 0 0 0</pose>
      <inertial>
        <pose>0.045282999999999997 -0.0044812999999999997 -0.0010646 0 0 0</pose>
        <mass>0.034680999999999997</mass>
        <inertia>
          <ixx>1.6475000000000001e-05</ixx>
          <ixy>9.8629999999999998e-07</ixy>
          <ixz>4.8663999999999998e-08</ixz>
          <iyy>2.0945999999999999e-05</iyy>
          <iyz>6.4551000000000002e-09</iyz>
          <izz>9.0401000000000001e-06</izz>
        </inertia>
      </inertial>
      <collision name='br_knee_collision'>
        <pose>0 0 0 0 0 0</pose>
        <geometry>
          <mesh>
            <scale>1 1 1</scale>
            <uri>model://THex_Quadruped/meshes/br_knee_collision.STL</uri>
          </mesh>
        </geometry>
      </collision>
      <visual name='br_knee_visual'>
        <pose>0 0 0 0 0 0</pose>
        <geometry>
          <mesh>
            <scale>1 1 1</scale>
            <uri>model://THex_Quadruped/meshes/br_knee.STL</uri>
          </mesh>
        </geometry>
        <material>
          <diffuse>1 1 1 1</diffuse>
          <ambient>1 1 1 1</ambient>
        </material>
      </visual>
    </link>
    <joint name='br_foot_joint' type='revolute'>
      <pose relative_to='br_knee'>0.073065000000000005 -0.018655999999999999 -0.00012210000000000001 -3.1368999999999998 0.0045678000000000021 -2.3433000000000002</pose>
      <parent>br_knee</parent>
      <child>br_foot</child>
      <axis>
        <xyz>0 0 1</xyz>
        <limit>
          <lower>-1.5707</lower>
          <upper>1.5707</upper>
          <effort>0.94140000000000001</effort>
          <velocity>5.2300000000000004</velocity>
        </limit>
        <dynamics>
          <spring_reference>0</spring_reference>
          <spring_stiffness>0</spring_stiffness>
        </dynamics>
      </axis>
    </joint>
    <link name='br_foot'>
      <pose relative_to='br_foot_joint'>0 0 0 0 0 0</pose>
      <inertial>
        <pose>0.020857000000000001 -0.003581 -0.0013921000000000001 0 0 0</pose>
        <mass>0.057595</mass>
        <inertia>
          <ixx>6.4423000000000001e-06</ixx>
          <ixy>-3.9831000000000002e-07</ixy>
          <ixz>1.4001000000000001e-08</ixz>
          <iyy>1.1705000000000001e-05</iyy>
          <iyz>3.7381999999999999e-07</iyz>
          <izz>9.2683000000000007e-06</izz>
        </inertia>
      </inertial>
      <collision name='br_foot_collision'>
        <pose>0 0 0 0 0 0</pose>
        <geometry>
          <mesh>
            <scale>1 1 1</scale>
            <uri>model://THex_Quadruped/meshes/br_foot_collision.STL</uri>
          </mesh>
        </geometry>
      </collision>
      <visual name='br_foot_visual'>
        <pose>0 0 0 0 0 0</pose>
        <geometry>
          <mesh>
            <scale>1 1 1</scale>
            <uri>model://THex_Quadruped/meshes/br_foot.STL</uri>
          </mesh>
        </geometry>
        <material>
          <diffuse>1 1 1 1</diffuse>
          <ambient>1 1 1 1</ambient>
        </material>
      </visual>
    </link>
    <joint name='fl_hip_joint' type='revolute'>
      <pose relative_to='base_link'>-0.059512000000000002 0.078853999999999994 0 0 0 2.3666</pose>
      <parent>base_link</parent>
      <child>fl_hip</child>
      <axis>
        <xyz>0 0 1</xyz>
        <limit>
          <lower>-0.7853</lower>
          <upper>0.7853</upper>
          <effort>0.94140000000000001</effort>
          <velocity>5.2300000000000004</velocity>
        </limit>
        <dynamics>
          <spring_reference>0</spring_reference>
          <spring_stiffness>0</spring_stiffness>
        </dynamics>
      </axis>
    </joint>
    <link name='fl_hip'>
      <pose relative_to='fl_hip_joint'>0 0 0 0 0 0</pose>
      <inertial>
        <pose>0.015006 0.0056423000000000003 0.012298999999999999 0 0 0</pose>
        <mass>0.080321000000000004</mass>
        <inertia>
          <ixx>1.9522e-05</ixx>
          <ixy>-4.3980000000000001e-07</ixy>
          <ixz>-3.7380000000000003e-07</ixz>
          <iyy>1.261e-05</iyy>
          <iyz>6.3953e-09</iyz>
          <izz>1.2576e-05</izz>
        </inertia>
      </inertial>
      <collision name='fl_hip_collision'>
        <pose>0 0 0 0 0 0</pose>
        <geometry>
          <mesh>
            <scale>1 1 1</scale>
            <uri>model://THex_Quadruped/meshes/fl_hip_collision.STL</uri>
          </mesh>
        </geometry>
      </collision>
      <visual name='fl_hip_visual'>
        <pose>0 0 0 0 0 0</pose>
        <geometry>
          <mesh>
            <scale>1 1 1</scale>
            <uri>model://THex_Quadruped/meshes/fl_hip.STL</uri>
          </mesh>
        </geometry>
        <material>
          <diffuse>1 1 1 1</diffuse>
          <ambient>1 1 1 1</ambient>
        </material>
      </visual>
    </link>
    <joint name='fl_knee_joint' type='revolute'>
      <pose relative_to='fl_hip'>0.028448999999999999 0 0 -1.5774999999999999 -0.78537999999999997 -7.8503197062369069e-17</pose>
      <parent>fl_hip</parent>
      <child>fl_knee</child>
      <axis>
        <xyz>-0.0067371999999999996 0 -0.99997999999999998</xyz>
        <limit>
          <lower>-1.5707</lower>
          <upper>1.5707</upper>
          <effort>0.94140000000000001</effort>
          <velocity>5.2300000000000004</velocity>
        </limit>
        <dynamics>
          <spring_reference>0</spring_reference>
          <spring_stiffness>0</spring_stiffness>
        </dynamics>
      </axis>
    </joint>
    <link name='fl_knee'>
      <pose relative_to='fl_knee_joint'>0 0 0 0 0 0</pose>
      <inertial>
        <pose>0.045273000000000001 0.0044812999999999997 -0.00044768999999999999 0 0 0</pose>
        <mass>0.034680999999999997</mass>
        <inertia>
          <ixx>1.6475000000000001e-05</ixx>
          <ixy>-9.8629999999999998e-07</ixy>
          <ixz>-5.0096000000000001e-08</ixz>
          <iyy>2.0945999999999999e-05</iyy>
          <iyz>6.6452000000000002e-09</iyz>
          <izz>9.0402000000000003e-06</izz>
        </inertia>
      </inertial>
      <collision name='fl_knee_collision'>
        <pose>0 0 0 0 0 0</pose>
        <geometry>
          <mesh>
            <scale>1 1 1</scale>
            <uri>model://THex_Quadruped/meshes/fl_knee_collision.STL</uri>
          </mesh>
        </geometry>
      </collision>
      <visual name='fl_knee_visual'>
        <pose>0 0 0 0 0 0</pose>
        <geometry>
          <mesh>
            <scale>1 1 1</scale>
            <uri>model://THex_Quadruped/meshes/fl_knee.STL</uri>
          </mesh>
        </geometry>
        <material>
          <diffuse>1 1 1 1</diffuse>
          <ambient>1 1 1 1</ambient>
        </material>
      </visual>
    </link>
    <joint name='fl_foot_joint' type='revolute'>
      <pose relative_to='fl_knee'>0.073066000000000006 0.018655999999999999 0.00012569 -3.1368 -0.0047025000000000001 2.3433999999999999</pose>
      <parent>fl_knee</parent>
      <child>fl_foot</child>
      <axis>
        <xyz>0 0 1</xyz>
        <limit>
          <lower>-1.5707</lower>
          <upper>1.5707</upper>
          <effort>0.94140000000000001</effort>
          <velocity>5.2300000000000004</velocity>
        </limit>
        <dynamics>
          <spring_reference>0</spring_reference>
          <spring_stiffness>0</spring_stiffness>
        </dynamics>
      </axis>
    </joint>
    <link name='fl_foot'>
      <pose relative_to='fl_foot_joint'>0 0 0 0 0 0</pose>
      <inertial>
        <pose>0.021142000000000001 0.0035788 -0.0013921000000000001 0 0 0</pose>
        <mass>0.057595</mass>
        <inertia>
          <ixx>6.4423000000000001e-06</ixx>
          <ixy>3.9845000000000002e-07</ixy>
          <ixz>1.1196e-08</ixz>
          <iyy>1.1705000000000001e-05</iyy>
          <iyz>-3.7378e-07</iyz>
          <izz>9.2683000000000007e-06</izz>
        </inertia>
      </inertial>
      <collision name='fl_foot_collision'>
        <pose>0 0 0 0 0 0</pose>
        <geometry>
          <mesh>
            <scale>1 1 1</scale>
            <uri>model://THex_Quadruped/meshes/fl_foot_collision.STL</uri>
          </mesh>
        </geometry>
      </collision>
      <visual name='fl_foot_visual'>
        <pose>0 0 0 0 0 0</pose>
        <geometry>
          <mesh>
            <scale>1 1 1</scale>
            <uri>model://THex_Quadruped/meshes/fl_foot.STL</uri>
          </mesh>
        </geometry>
        <material>
          <diffuse>1 1 1 1</diffuse>
          <ambient>1 1 1 1</ambient>
        </material>
      </visual>
    </link>
    <joint name='fr_hip_joint' type='revolute'>
      <pose relative_to='base_link'>0.059512000000000002 0.078853999999999994 0.00053339999999999995 0 0 0.76931000000000005</pose>
      <parent>base_link</parent>
      <child>fr_hip</child>
      <axis>
        <xyz>0 0 1</xyz>
        <limit>
          <lower>-0.7853</lower>
          <upper>0.7853</upper>
          <effort>0.94140000000000001</effort>
          <velocity>5.2300000000000004</velocity>
        </limit>
        <dynamics>
          <spring_reference>0</spring_reference>
          <spring_stiffness>0</spring_stiffness>
        </dynamics>
      </axis>
    </joint>
    <link name='fr_hip'>
      <pose relative_to='fr_hip_joint'>0 0 0 0 0 0</pose>
      <inertial>
        <pose>0.015044 -0.0059121 0.011971000000000001 0 0 0</pose>
        <mass>0.080321000000000004</mass>
        <inertia>
          <ixx>1.9516000000000001e-05</ixx>
          <ixy>4.7874000000000001e-07</ixy>
          <ixz>-3.7331e-07</ixz>
          <iyy>1.2616000000000001e-05</iyy>
          <iyz>-2.8574000000000001e-09</iyz>
          <izz>1.2576e-05</izz>
        </inertia>
      </inertial>
      <collision name='fr_hip_collision'>
        <pose>0 0 0 0 0 0</pose>
        <geometry>
          <mesh>
            <scale>1 1 1</scale>
            <uri>model://THex_Quadruped/meshes/fr_hip_collision.STL</uri>
          </mesh>
        </geometry>
      </collision>
      <visual name='fr_hip_visual'>
        <pose>0 0 0 0 0 0</pose>
        <geometry>
          <mesh>
            <scale>1 1 1</scale>
            <uri>model://THex_Quadruped/meshes/fr_hip.STL</uri>
          </mesh>
        </geometry>
        <material>
          <diffuse>1 1 1 1</diffuse>
          <ambient>1 1 1 1</ambient>
        </material>
      </visual>
    </link>
    <joint name='fr_knee_joint' type='revolute'>
      <pose relative_to='fr_hip'>0.028451000000000001 0 0 1.5816000000000001 -0.78534000000000004 0</pose>
      <parent>fr_hip</parent>
      <child>fr_knee</child>
      <axis>
        <xyz>-0.010779 0 -0.99994000000000005</xyz>
        <limit>
          <lower>-1.5707</lower>
          <upper>1.5707</upper>
          <effort>0.94140000000000001</effort>
          <velocity>5.2300000000000004</velocity>
        </limit>
        <dynamics>
          <spring_reference>0</spring_reference>
          <spring_stiffness>0</spring_stiffness>
        </dynamics>
      </axis>
    </joint>
    <link name='fr_knee'>
      <pose relative_to='fr_knee_joint'>0 0 0 0 0 0</pose>
      <inertial>
        <pose>0.045275000000000003 -0.0044812999999999997 -0.00025994000000000001 0 0 0</pose>
        <mass>0.034680999999999997</mass>
        <inertia>
          <ixx>1.6475000000000001e-05</ixx>
          <ixy>9.8627e-07</ixy>
          <ixz>-8.0146999999999996e-08</ixz>
          <iyy>2.0945999999999999e-05</iyy>
          <iyz>-1.0632000000000001e-08</iyz>
          <izz>9.0406999999999997e-06</izz>
        </inertia>
      </inertial>
      <collision name='fr_knee_collision'>
        <pose>0 0 0 0 0 0</pose>
        <geometry>
          <mesh>
            <scale>1 1 1</scale>
            <uri>model://THex_Quadruped/meshes/fr_knee_collision.STL</uri>
          </mesh>
        </geometry>
      </collision>
      <visual name='fr_knee_visual'>
        <pose>0 0 0 0 0 0</pose>
        <geometry>
          <mesh>
            <scale>1 1 1</scale>
            <uri>model://THex_Quadruped/meshes/fr_knee.STL</uri>
          </mesh>
        </geometry>
        <material>
          <diffuse>1 1 1 1</diffuse>
          <ambient>1 1 1 1</ambient>
        </material>
      </visual>
    </link>
    <joint name='fr_foot_joint' type='revolute'>
      <pose relative_to='fr_knee'>0.073069999999999996 -0.018655999999999999 0.00020110000000000001 3.1339000000000001 -0.0075232000000000007 -2.3433000000000002</pose>
      <parent>fr_knee</parent>
      <child>fr_foot</child>
      <axis>
        <xyz>0 0 1</xyz>
        <limit>
          <lower>-1.5707</lower>
          <upper>1.5707</upper>
          <effort>0.94140000000000001</effort>
          <velocity>5.2300000000000004</velocity>
        </limit>
        <dynamics>
          <spring_reference>0</spring_reference>
          <spring_stiffness>0</spring_stiffness>
        </dynamics>
      </axis>
    </joint>
    <link name='fr_foot'>
      <pose relative_to='fr_foot_joint'>0 0 0 0 0 0</pose>
      <inertial>
        <pose>0.020857000000000001 -0.003581 -0.0013921000000000001 0 0 0</pose>
        <mass>0.057595</mass>
        <inertia>
          <ixx>6.4423000000000001e-06</ixx>
          <ixy>-3.9831000000000002e-07</ixy>
          <ixz>1.4001000000000001e-08</ixz>
          <iyy>1.1705000000000001e-05</iyy>
          <iyz>3.7381999999999999e-07</iyz>
          <izz>9.2683000000000007e-06</izz>
        </inertia>
      </inertial>
      <collision name='fr_foot_collision'>
        <pose>0 0 0 0 0 0</pose>
        <geometry>
          <mesh>
            <scale>1 1 1</scale>
            <uri>model://THex_Quadruped/meshes/fr_foot_collision.STL</uri>
          </mesh>
        </geometry>
      </collision>
      <visual name='fr_foot_visual'>
        <pose>0 0 0 0 0 0</pose>
        <geometry>
          <mesh>
            <scale>1 1 1</scale>
            <uri>model://THex_Quadruped/meshes/fr_foot.STL</uri>
          </mesh>
        </geometry>
        <material>
          <diffuse>1 1 1 1</diffuse>
          <ambient>1 1 1 1</ambient>
        </material>
      </visual>
    </link>
  </model>
</sdf>
