<sdf version='1.11'>
  <model name='THex_Quadruped'>
  <self_collide>true</self_collide>
    <link name='base_link'>
      <inertial>
        <pose>0.00018 -0.00861 0.03579 0 0 0</pose>
        <mass>0.30423</mass>
        <inertia>
          <ixx>0.00232</ixx>
          <ixy>0</ixy>
          <ixz>0</ixz>
          <iyy>0.00064</iyy>
          <iyz>0.00008</iyz>
          <izz>0.00225</izz>
        </inertia>
      </inertial>
      <collision name='base_link_collision'>
        <pose>0 0 0 0 0 0</pose>
        <geometry>
          <mesh>
            <scale>1 1 1</scale>
            <uri>model://THex_Quadruped/meshes/base_link_collision.STL</uri>
          </mesh>
        </geometry>
      </collision>
      <visual name='base_link_visual'>
        <pose>0 0 0 0 0 0</pose>
        <geometry>
          <mesh>
            <scale>1 1 1</scale>
            <uri>model://THex_Quadruped/meshes/base_link.STL</uri>
          </mesh>
        </geometry>
        <material>
          <diffuse>1 1 1 1</diffuse>
          <ambient>1 1 1 1</ambient>
        </material>
      </visual>
    </link>
    <joint name='bl_hip_joint' type='revolute'>
      <pose relative_to='base_link'>-0.053156000000000002 -0.12709000000000001 0 0 0 -2.3570000000000002</pose>
      <parent>base_link</parent>
      <child>bl_hip</child>
      <axis>
        <xyz>0 0 1</xyz>
        <limit>
          <lower>-0.7853</lower>
          <upper>0.7853</upper>
          <effort>0.9414</effort>
          <velocity>5.23</velocity>
        </limit>
        <dynamics>
          <spring_reference>0</spring_reference>
          <spring_stiffness>0</spring_stiffness>
        </dynamics>
      </axis>
      <physics>
        <provide_feedback>true</provide_feedback>
      </physics>
      <sensor name="force_torque_sensor" type="force_torque">
        <update_rate>100</update_rate>
        <always_on>true</always_on>
        <visualize>true</visualize>
        <topic>bl_hip_force_torque</topic>
        <force_torque>
          <frame>sensor</frame>
          <measure_direction>parent_to_child</measure_direction>
        </force_torque>
      </sensor>
    </joint>
    <link name='bl_hip'>
      <pose relative_to='bl_hip_joint'>0 0 0 0 0 0</pose>
      <inertial>
        <pose>0.01464 -0.00468 0.01291 0 0 0</pose>
        <mass>0.14763</mass>
        <inertia>
          <ixx>0.00005</ixx>
          <ixy>0.00001</ixy>
          <ixz>-0.00001</ixz>
          <iyy>0.00005</iyy>
          <iyz>0</iyz>
          <izz>0.00006</izz>
        </inertia>
      </inertial>
      <collision name='bl_hip_collision'>
        <pose>0 0 0 0 0 0</pose>
        <geometry>
          <mesh>
            <scale>1 1 1</scale>
            <uri>model://THex_Quadruped/meshes/bl_hip_collision.STL</uri>
          </mesh>
        </geometry>
      </collision>
      <visual name='bl_hip_visual'>
        <pose>0 0 0 0 0 0</pose>
        <geometry>
          <mesh>
            <scale>1 1 1</scale>
            <uri>model://THex_Quadruped/meshes/bl_hip.STL</uri>
          </mesh>
        </geometry>
        <material>
          <diffuse>1 1 1 1</diffuse>
          <ambient>1 1 1 1</ambient>
        </material>
      </visual>
    </link>
    <joint name='bl_knee_joint' type='revolute'>
      <pose relative_to='bl_hip'>0.028468 0 0 -1.5707 0 -0.071951000000000015</pose>
      <parent>bl_hip</parent>
      <child>bl_knee</child>
      <axis>
        <xyz>0 0 1</xyz>
        <limit>
          <lower>-1.5707</lower>
          <upper>1.5707</upper>
          <effort>0.9414</effort>
          <velocity>5.23</velocity>
        </limit>
        <dynamics>
          <spring_reference>0</spring_reference>
          <spring_stiffness>0</spring_stiffness>
        </dynamics>
      </axis>
      <physics>
        <provide_feedback>true</provide_feedback>
      </physics>
      <sensor name="force_torque_sensor" type="force_torque">
        <update_rate>100</update_rate>
        <always_on>true</always_on>
        <visualize>true</visualize>
        <topic>bl_knee_force_torque</topic>
        <force_torque>
          <frame>sensor</frame>
          <measure_direction>parent_to_child</measure_direction>
        </force_torque>
      </sensor>
    </joint>
    <link name='bl_knee'>
      <pose relative_to='bl_knee_joint'>0 0 0 0 0 0</pose>
      <inertial>
        <pose>0.04532 0.00448 0.00015 0 0 0</pose>
        <mass>0.03468</mass>
        <inertia>
          <ixx>0.00002</ixx>
          <ixy>0</ixy>
          <ixz>0</ixz>
          <iyy>0.00003</iyy>
          <iyz>0</iyz>
          <izz>0.00002</izz>
        </inertia>
      </inertial>
      <collision name='bl_knee_collision'>
        <pose>0 0 0 0 0 0</pose>
        <geometry>
          <mesh>
            <scale>1 1 1</scale>
            <uri>model://THex_Quadruped/meshes/bl_knee_collision.STL</uri>
          </mesh>
        </geometry>
      </collision>
      <visual name='bl_knee_visual'>
        <pose>0 0 0 0 0 0</pose>
        <geometry>
          <mesh>
            <scale>1 1 1</scale>
            <uri>model://THex_Quadruped/meshes/bl_knee.STL</uri>
          </mesh>
        </geometry>
        <material>
          <diffuse>1 1 1 1</diffuse>
          <ambient>1 1 1 1</ambient>
        </material>
      </visual>
    </link>
    <joint name='bl_foot_joint' type='revolute'>
      <pose relative_to='bl_knee'>0.072935 0.018648999999999999 0 3.1415 0 0.7853</pose>
      <parent>bl_knee</parent>
      <child>bl_foot</child>
      <axis>
        <xyz>0 0 1</xyz>
        <limit>
          <lower>-1.5707</lower>
          <upper>1.5707</upper>
          <effort>0.9414</effort>
          <velocity>5.23</velocity>
        </limit>
        <dynamics>
          <spring_reference>0</spring_reference>
          <spring_stiffness>0</spring_stiffness>
        </dynamics>
      </axis>
      <physics>
        <provide_feedback>true</provide_feedback>
      </physics>
      <sensor name="force_torque_sensor" type="force_torque">
        <update_rate>100</update_rate>
        <always_on>true</always_on>
        <visualize>true</visualize>
        <topic>bl_foot_force_torque</topic>
        <force_torque>
          <frame>sensor</frame>
          <measure_direction>parent_to_child</measure_direction>
        </force_torque>
      </sensor>
    </joint>
    <link name='bl_foot'>
      <pose relative_to='bl_foot_joint'>0 0 0 0 0 0</pose>
      <inertial>
        <pose>0.01684 0.00222 0.00042 0 0 0</pose>
        <mass>0.09125</mass>
        <inertia>
          <ixx>0.00001</ixx>
          <ixy>0</ixy>
          <ixz>0</ixz>
          <iyy>0.00004</iyy>
          <iyz>0</iyz>
          <izz>0.00004</izz>
        </inertia>
      </inertial>
      <collision name='bl_foot_collision'>
        <pose>0 0 0 0 0 0</pose>
        <geometry>
          <mesh>
            <scale>1 1 1</scale>
            <uri>model://THex_Quadruped/meshes/bl_foot_collision.STL</uri>
          </mesh>
        </geometry>
      </collision>
      <visual name='bl_foot_visual'>
        <pose>0 0 0 0 0 0</pose>
        <geometry>
          <mesh>
            <scale>1 1 1</scale>
            <uri>model://THex_Quadruped/meshes/bl_foot.STL</uri>
          </mesh>
        </geometry>
        <material>
          <diffuse>1 1 1 1</diffuse>
          <ambient>1 1 1 1</ambient>
        </material>
      </visual>
    </link>
    <joint name='br_hip_joint' type='revolute'>
      <pose relative_to='base_link'>0.053156000000000002 -0.12709000000000001 0 0 0 -0.78456000000000026</pose>
      <parent>base_link</parent>
      <child>br_hip</child>
      <axis>
        <xyz>0 0 1</xyz>
        <limit>
          <lower>-0.7853</lower>
          <upper>0.7853</upper>
          <effort>0.9414</effort>
          <velocity>5.23</velocity>
        </limit>
        <dynamics>
          <spring_reference>0</spring_reference>
          <spring_stiffness>0</spring_stiffness>
        </dynamics>
      </axis>
      <physics>
        <provide_feedback>true</provide_feedback>
      </physics>
      <sensor name="force_torque_sensor" type="force_torque">
        <update_rate>100</update_rate>
        <always_on>true</always_on>
        <visualize>true</visualize>
        <topic>br_hip_force_torque</topic>
        <force_torque>
          <frame>sensor</frame>
          <measure_direction>parent_to_child</measure_direction>
        </force_torque>
      </sensor>
    </joint>
    <link name='br_hip'>
      <pose relative_to='br_hip_joint'>0 0 0 0 0 0</pose>
      <inertial>
        <pose>0.01464 0.00436 0.01261 0 0 0</pose>
        <mass>0.14763</mass>
        <inertia>
          <ixx>0.00005</ixx>
          <ixy>-0.00001</ixy>
          <ixz>-0.00001</ixz>
          <iyy>0.00005</iyy>
          <iyz>0</iyz>
          <izz>0.00006</izz>
        </inertia>
      </inertial>
      <collision name='br_hip_collision'>
        <pose>0 0 0 0 0 0</pose>
        <geometry>
          <mesh>
            <scale>1 1 1</scale>
            <uri>model://THex_Quadruped/meshes/br_hip_collision.STL</uri>
          </mesh>
        </geometry>
      </collision>
      <visual name='br_hip_visual'>
        <pose>0 0 0 0 0 0</pose>
        <geometry>
          <mesh>
            <scale>1 1 1</scale>
            <uri>model://THex_Quadruped/meshes/br_hip.STL</uri>
          </mesh>
        </geometry>
        <material>
          <diffuse>1 1 1 1</diffuse>
          <ambient>1 1 1 1</ambient>
        </material>
      </visual>
    </link>
    <joint name='br_knee_joint' type='revolute'>
      <pose relative_to='br_hip'>0.028468 0 0 1.5707 0 0</pose>
      <parent>br_hip</parent>
      <child>br_knee</child>
      <axis>
        <xyz>0 0 1</xyz>
        <limit>
          <lower>-1.5707</lower>
          <upper>1.5707</upper>
          <effort>0.9414</effort>
          <velocity>5.23</velocity>
        </limit>
        <dynamics>
          <spring_reference>0</spring_reference>
          <spring_stiffness>0</spring_stiffness>
        </dynamics>
      </axis>
      <physics>
        <provide_feedback>true</provide_feedback>
      </physics>
      <sensor name="force_torque_sensor" type="force_torque">
        <update_rate>100</update_rate>
        <always_on>true</always_on>
        <visualize>true</visualize>
        <topic>br_knee_force_torque</topic>
        <force_torque>
          <frame>sensor</frame>
          <measure_direction>parent_to_child</measure_direction>
        </force_torque>
      </sensor>
    </joint>
    <link name='br_knee'>
      <pose relative_to='br_knee_joint'>0 0 0 0 0 0</pose>
      <inertial>
        <pose>0.04530 -0.00448 0.00016 0 0 0</pose>
        <mass>0.03468</mass>
        <inertia>
          <ixx>0.00002</ixx>
          <ixy>0</ixy>
          <ixz>0</ixz>
          <iyy>0.00003</iyy>
          <iyz>0</iyz>
          <izz>0.00002</izz>
        </inertia>
      </inertial>
      <collision name='br_knee_collision'>
        <pose>0 0 0 0 0 0</pose>
        <geometry>
          <mesh>
            <scale>1 1 1</scale>
            <uri>model://THex_Quadruped/meshes/br_knee_collision.STL</uri>
          </mesh>
        </geometry>
      </collision>
      <visual name='br_knee_visual'>
        <pose>0 0 0 0 0 0</pose>
        <geometry>
          <mesh>
            <scale>1 1 1</scale>
            <uri>model://THex_Quadruped/meshes/br_knee.STL</uri>
          </mesh>
        </geometry>
        <material>
          <diffuse>1 1 1 1</diffuse>
          <ambient>1 1 1 1</ambient>
        </material>
      </visual>
    </link>
    <joint name='br_foot_joint' type='revolute'>
      <pose relative_to='br_knee'>0.072955999999999993 -0.018648999999999999 0 -3.1415 0 -0.7853</pose>
      <parent>br_knee</parent>
      <child>br_foot</child>
      <axis>
        <xyz>0 0 1</xyz>
        <limit>
          <lower>-1.5707</lower>
          <upper>1.5707</upper>
          <effort>0.9414</effort>
          <velocity>5.23</velocity>
        </limit>
        <dynamics>
          <spring_reference>0</spring_reference>
          <spring_stiffness>0</spring_stiffness>
        </dynamics>
      </axis>
      <physics>
        <provide_feedback>true</provide_feedback>
      </physics>
      <sensor name="force_torque_sensor" type="force_torque">
        <update_rate>100</update_rate>
        <always_on>true</always_on>
        <visualize>true</visualize>
        <topic>br_foot_force_torque</topic>
        <force_torque>
          <frame>sensor</frame>
          <measure_direction>parent_to_child</measure_direction>
        </force_torque>
      </sensor>
    </joint>
    <link name='br_foot'>
      <pose relative_to='br_foot_joint'>0 0 0 0 0 0</pose>
      <inertial>
        <pose>0.01666 -0.00222 0.00043 0 0 0</pose>
        <mass>0.09125</mass>
        <inertia>
          <ixx>0.00001</ixx>
          <ixy>0</ixy>
          <ixz>0</ixz>
          <iyy>0.00004</iyy>
          <iyz>0</iyz>
          <izz>0.00004</izz>
        </inertia>
      </inertial>
      <collision name='br_foot_collision'>
        <pose>0 0 0 0 0 0</pose>
        <geometry>
          <mesh>
            <scale>1 1 1</scale>
            <uri>model://THex_Quadruped/meshes/br_foot_collision.STL</uri>
          </mesh>
        </geometry>
      </collision>
      <visual name='br_foot_visual'>
        <pose>0 0 0 0 0 0</pose>
        <geometry>
          <mesh>
            <scale>1 1 1</scale>
            <uri>model://THex_Quadruped/meshes/br_foot.STL</uri>
          </mesh>
        </geometry>
        <material>
          <diffuse>1 1 1 1</diffuse>
          <ambient>1 1 1 1</ambient>
        </material>
      </visual>
    </link>
    <joint name='fl_hip_joint' type='revolute'>
      <pose relative_to='base_link'>-0.059506000000000003 0.078833 0 0 0 2.3570000000000002</pose>
      <parent>base_link</parent>
      <child>fl_hip</child>
      <axis>
        <xyz>0 0 1</xyz>
        <limit>
          <lower>-0.7853</lower>
          <upper>0.7853</upper>
          <effort>0.9414</effort>
          <velocity>5.23</velocity>
        </limit>
        <dynamics>
          <spring_reference>0</spring_reference>
          <spring_stiffness>0</spring_stiffness>
        </dynamics>
      </axis>
      <physics>
        <provide_feedback>true</provide_feedback>
      </physics>
      <sensor name="force_torque_sensor" type="force_torque">
        <update_rate>100</update_rate>
        <always_on>true</always_on>
        <visualize>true</visualize>
        <topic>fl_hip_force_torque</topic>
        <force_torque>
          <frame>sensor</frame>
          <measure_direction>parent_to_child</measure_direction>
        </force_torque>
      </sensor>
    </joint>
    <link name='fl_hip'>
      <pose relative_to='fl_hip_joint'>0 0 0 0 0 0</pose>
      <inertial>
        <pose>0.01464 0.00557 0.01291 0 0 0</pose>
        <mass>0.14763</mass>
        <inertia>
          <ixx>0.00005</ixx>
          <ixy>-0.00001</ixy>
          <ixz>-0.00001</ixz>
          <iyy>0.00005</iyy>
          <iyz>0</iyz>
          <izz>0.00006</izz>
        </inertia>
      </inertial>
      <collision name='fl_hip_collision'>
        <pose>0 0 0 0 0 0</pose>
        <geometry>
          <mesh>
            <scale>1 1 1</scale>
            <uri>model://THex_Quadruped/meshes/fl_hip_collision.STL</uri>
          </mesh>
        </geometry>
      </collision>
      <visual name='fl_hip_visual'>
        <pose>0 0 0 0 0 0</pose>
        <geometry>
          <mesh>
            <scale>1 1 1</scale>
            <uri>model://THex_Quadruped/meshes/fl_hip.STL</uri>
          </mesh>
        </geometry>
        <material>
          <diffuse>1 1 1 1</diffuse>
          <ambient>1 1 1 1</ambient>
        </material>
      </visual>
    </link>
    <joint name='fl_knee_joint' type='revolute'>
      <pose relative_to='fl_hip'>0.028468 0 0 -1.5707 0 0</pose>
      <parent>fl_hip</parent>
      <child>fl_knee</child>
      <axis>
        <xyz>0 0 1</xyz>
        <limit>
          <lower>-1.5707</lower>
          <upper>1.5707</upper>
          <effort>0.9414</effort>
          <velocity>5.23</velocity>
        </limit>
        <dynamics>
          <spring_reference>0</spring_reference>
          <spring_stiffness>0</spring_stiffness>
        </dynamics>
      </axis>
      <physics>
        <provide_feedback>true</provide_feedback>
      </physics>
      <sensor name="force_torque_sensor" type="force_torque">
        <update_rate>100</update_rate>
        <always_on>true</always_on>
        <visualize>true</visualize>
        <topic>fl_knee_force_torque</topic>
        <force_torque>
          <frame>sensor</frame>
          <measure_direction>parent_to_child</measure_direction>
        </force_torque>
      </sensor>
    </joint>
    <link name='fl_knee'>
      <pose relative_to='fl_knee_joint'>0 0 0 0 0 0</pose>
      <inertial>
        <pose>0.04527 0.00448 0.00019 0 0 0</pose>
        <mass>0.03468</mass>
        <inertia>
          <ixx>0.00002</ixx>
          <ixy>0</ixy>
          <ixz>0</ixz>
          <iyy>0.00003</iyy>
          <iyz>0</iyz>
          <izz>0.00002</izz>
        </inertia>
      </inertial>
      <collision name='fl_knee_collision'>
        <pose>0 0 0 0 0 0</pose>
        <geometry>
          <mesh>
            <scale>1 1 1</scale>
            <uri>model://THex_Quadruped/meshes/fl_knee_collision.STL</uri>
          </mesh>
        </geometry>
      </collision>
      <visual name='fl_knee_visual'>
        <pose>0 0 0 0 0 0</pose>
        <geometry>
          <mesh>
            <scale>1 1 1</scale>
            <uri>model://THex_Quadruped/meshes/fl_knee.STL</uri>
          </mesh>
        </geometry>
        <material>
          <diffuse>1 1 1 1</diffuse>
          <ambient>1 1 1 1</ambient>
        </material>
      </visual>
    </link>
    <joint name='fl_foot_joint' type='revolute'>
      <pose relative_to='fl_knee'>0.073042999999999997 0.018648999999999999 0 3.1415 0 0.7853</pose>
      <parent>fl_knee</parent>
      <child>fl_foot</child>
      <axis>
        <xyz>0 0 1</xyz>
        <limit>
          <lower>-1.5707</lower>
          <upper>1.5707</upper>
          <effort>0.9414</effort>
          <velocity>5.23</velocity>
        </limit>
        <dynamics>
          <spring_reference>0</spring_reference>
          <spring_stiffness>0</spring_stiffness>
        </dynamics>
      </axis>
      <physics>
        <provide_feedback>true</provide_feedback>
      </physics>
      <sensor name="force_torque_sensor" type="force_torque">
        <update_rate>100</update_rate>
        <always_on>true</always_on>
        <visualize>true</visualize>
        <topic>fl_foot_force_torque</topic>
        <force_torque>
          <frame>sensor</frame>
          <measure_direction>parent_to_child</measure_direction>
        </force_torque>
      </sensor>
    </joint>
    <link name='fl_foot'>
      <pose relative_to='fl_foot_joint'>0 0 0 0 0 0</pose>
      <inertial>
        <pose>0.01684 0.00222 0.00042 0 0 0</pose>
        <mass>0.09125</mass>
        <inertia>
          <ixx>0.00001</ixx>
          <ixy>0</ixy>
          <ixz>0</ixz>
          <iyy>0.00004</iyy>
          <iyz>0</iyz>
          <izz>0.00004</izz>
        </inertia>
      </inertial>
      <collision name='fl_foot_collision'>
        <pose>0 0 0 0 0 0</pose>
        <geometry>
          <mesh>
            <scale>1 1 1</scale>
            <uri>model://THex_Quadruped/meshes/fl_foot_collision.STL</uri>
          </mesh>
        </geometry>
      </collision>
      <visual name='fl_foot_visual'>
        <pose>0 0 0 0 0 0</pose>
        <geometry>
          <mesh>
            <scale>1 1 1</scale>
            <uri>model://THex_Quadruped/meshes/fl_foot.STL</uri>
          </mesh>
        </geometry>
        <material>
          <diffuse>1 1 1 1</diffuse>
          <ambient>1 1 1 1</ambient>
        </material>
      </visual>
    </link>
    <joint name='fr_hip_joint' type='revolute'>
      <pose relative_to='base_link'>0.059506000000000003 0.078833 0 0 0 0.78456000000000026</pose>
      <parent>base_link</parent>
      <child>fr_hip</child>
      <axis>
        <xyz>0 0 1</xyz>
        <limit>
          <lower>-0.7853</lower>
          <upper>0.7853</upper>
          <effort>0.9414</effort>
          <velocity>5.23</velocity>
        </limit>
        <dynamics>
          <spring_reference>0</spring_reference>
          <spring_stiffness>0</spring_stiffness>
        </dynamics>
      </axis>
      <physics>
        <provide_feedback>true</provide_feedback>
      </physics>
      <sensor name="force_torque_sensor" type="force_torque">
        <update_rate>100</update_rate>
        <always_on>true</always_on>
        <visualize>true</visualize>
        <topic>fr_hip_force_torque</topic>
        <force_torque>
          <frame>sensor</frame>
          <measure_direction>parent_to_child</measure_direction>
        </force_torque>
      </sensor>
    </joint>
    <link name='fr_hip'>
      <pose relative_to='fr_hip_joint'>0 0 0 0 0 0</pose>
      <inertial>
        <pose>0.01464 -0.00588 0.01261 0 0 0</pose>
        <mass>0.14763</mass>
        <inertia>
          <ixx>0.00005</ixx>
          <ixy>0.00001</ixy>
          <ixz>-0.00001</ixz>
          <iyy>0.00005</iyy>
          <iyz>0</iyz>
          <izz>0.00006</izz>
        </inertia>
      </inertial>
      <collision name='fr_hip_collision'>
        <pose>0 0 0 0 0 0</pose>
        <geometry>
          <mesh>
            <scale>1 1 1</scale>
            <uri>model://THex_Quadruped/meshes/fr_hip_collision.STL</uri>
          </mesh>
        </geometry>
      </collision>
      <visual name='fr_hip_visual'>
        <pose>0 0 0 0 0 0</pose>
        <geometry>
          <mesh>
            <scale>1 1 1</scale>
            <uri>model://THex_Quadruped/meshes/fr_hip.STL</uri>
          </mesh>
        </geometry>
        <material>
          <diffuse>1 1 1 1</diffuse>
          <ambient>1 1 1 1</ambient>
        </material>
      </visual>
    </link>
    <joint name='fr_knee_joint' type='revolute'>
      <pose relative_to='fr_hip'>0.028468 0 0 1.5707 0 0</pose>
      <parent>fr_hip</parent>
      <child>fr_knee</child>
      <axis>
        <xyz>0 0 1</xyz>
        <limit>
          <lower>-1.5707</lower>
          <upper>1.5707</upper>
          <effort>0.9414</effort>
          <velocity>5.23</velocity>
        </limit>
        <dynamics>
          <spring_reference>0</spring_reference>
          <spring_stiffness>0</spring_stiffness>
        </dynamics>
      </axis>
      <physics>
        <provide_feedback>true</provide_feedback>
      </physics>
      <sensor name="force_torque_sensor" type="force_torque">
        <update_rate>100</update_rate>
        <always_on>true</always_on>
        <visualize>true</visualize>
        <topic>fr_knee_force_torque</topic>
        <force_torque>
          <frame>sensor</frame>
          <measure_direction>parent_to_child</measure_direction>
        </force_torque>
      </sensor>
    </joint>
    <link name='fr_knee'>
      <pose relative_to='fr_knee_joint'>0 0 0 0 0 0</pose>
      <inertial>
        <pose>0.04528 -0.00448 0.00020 0 0 0</pose>
        <mass>0.03468</mass>
        <inertia>
          <ixx>0.00002</ixx>
          <ixy>0</ixy>
          <ixz>0</ixz>
          <iyy>0.00003</iyy>
          <iyz>0</iyz>
          <izz>0.00002</izz>
        </inertia>
      </inertial>
      <collision name='fr_knee_collision'>
        <pose>0 0 0 0 0 0</pose>
        <geometry>
          <mesh>
            <scale>1 1 1</scale>
            <uri>model://THex_Quadruped/meshes/fr_knee_collision.STL</uri>
          </mesh>
        </geometry>
      </collision>
      <visual name='fr_knee_visual'>
        <pose>0 0 0 0 0 0</pose>
        <geometry>
          <mesh>
            <scale>1 1 1</scale>
            <uri>model://THex_Quadruped/meshes/fr_knee.STL</uri>
          </mesh>
        </geometry>
        <material>
          <diffuse>1 1 1 1</diffuse>
          <ambient>1 1 1 1</ambient>
        </material>
      </visual>
    </link>
    <joint name='fr_foot_joint' type='revolute'>
      <pose relative_to='fr_knee'>0.073075000000000001 -0.018648999999999999 0 3.1415 0 -0.7853</pose>
      <parent>fr_knee</parent>
      <child>fr_foot</child>
      <axis>
        <xyz>0 0 1</xyz>
        <limit>
          <lower>-1.5707</lower>
          <upper>1.5707</upper>
          <effort>0.9414</effort>
          <velocity>5.23</velocity>
        </limit>
        <dynamics>
          <spring_reference>0</spring_reference>
          <spring_stiffness>0</spring_stiffness>
        </dynamics>
      </axis>
      <physics>
        <provide_feedback>true</provide_feedback>
      </physics>
      <sensor name="force_torque_sensor" type="force_torque">
        <update_rate>100</update_rate>
        <always_on>true</always_on>
        <visualize>true</visualize>
        <topic>fr_foot_force_torque</topic>
        <force_torque>
          <frame>sensor</frame>
          <measure_direction>parent_to_child</measure_direction>
        </force_torque>
      </sensor>
    </joint>
    <link name='fr_foot'>
      <pose relative_to='fr_foot_joint'>0 0 0 0 0 0</pose>
      <inertial>
        <pose>0.01666 -0.00222 0.00043 0 0 0</pose>
        <mass>0.09125</mass>
        <inertia>
          <ixx>0.00001</ixx>
          <ixy>0</ixy>
          <ixz>0</ixz>
          <iyy>0.00004</iyy>
          <iyz>0</iyz>
          <izz>0.00004</izz>
        </inertia>
      </inertial>
      <collision name='fr_foot_collision'>
        <pose>0 0 0 0 0 0</pose>
        <geometry>
          <mesh>
            <scale>1 1 1</scale>
            <uri>model://THex_Quadruped/meshes/fr_foot_collision.STL</uri>
          </mesh>
        </geometry>
      </collision>
      <visual name='fr_foot_visual'>
        <pose>0 0 0 0 0 0</pose>
        <geometry>
          <mesh>
            <scale>1 1 1</scale>
            <uri>model://THex_Quadruped/meshes/fr_foot.STL</uri>
          </mesh>
        </geometry>
        <material>
          <diffuse>1 1 1 1</diffuse>
          <ambient>1 1 1 1</ambient>
        </material>
      </visual>
    </link>
    <plugin name="gz::sim::systems::JointPositionController" filename="libgz-sim-joint-position-controller-system.so">
  	<joint_name>fr_hip_joint</joint_name>
    <use_velocity_commands>false</use_velocity_commands>
    <p_gain>5</p_gain>
    <i_gain>0.1</i_gain>
    <d_gain>0.1</d_gain>
    </plugin>
    <plugin name="gz::sim::systems::JointPositionController" filename="libgz-sim-joint-position-controller-system.so">
  	<joint_name>fr_knee_joint</joint_name>
    <use_velocity_commands>false</use_velocity_commands>
    <p_gain>5</p_gain>
    <i_gain>0.1</i_gain>
    <d_gain>0.1</d_gain>
    </plugin>
    <plugin name="gz::sim::systems::JointPositionController" filename="libgz-sim-joint-position-controller-system.so">
  	<joint_name>fr_foot_joint</joint_name>
    <use_velocity_commands>false</use_velocity_commands>
    <p_gain>5</p_gain>
    <i_gain>0.1</i_gain>
    <d_gain>0.1</d_gain>
    </plugin>
    <plugin name="gz::sim::systems::JointPositionController" filename="libgz-sim-joint-position-controller-system.so">
  	<joint_name>fl_hip_joint</joint_name>
    <use_velocity_commands>false</use_velocity_commands>
    <p_gain>5</p_gain>
    <i_gain>0.1</i_gain>
    <d_gain>0.1</d_gain>
    </plugin>
    <plugin name="gz::sim::systems::JointPositionController" filename="libgz-sim-joint-position-controller-system.so">
  	<joint_name>fl_knee_joint</joint_name>
    <use_velocity_commands>false</use_velocity_commands>
    <p_gain>5</p_gain>
    <i_gain>0.1</i_gain>
    <d_gain>0.1</d_gain>
    </plugin>
    <plugin name="gz::sim::systems::JointPositionController" filename="libgz-sim-joint-position-controller-system.so">
  	<joint_name>fl_foot_joint</joint_name>
    <use_velocity_commands>false</use_velocity_commands>
    <p_gain>5</p_gain>
    <i_gain>0.1</i_gain>
    <d_gain>0.1</d_gain>
    </plugin>
    <plugin name="gz::sim::systems::JointPositionController" filename="libgz-sim-joint-position-controller-system.so">
  	<joint_name>bl_hip_joint</joint_name>
    <use_velocity_commands>false</use_velocity_commands>
    <p_gain>5</p_gain>
    <i_gain>0.1</i_gain>
    <d_gain>0.1</d_gain>
    </plugin>
    <plugin name="gz::sim::systems::JointPositionController" filename="libgz-sim-joint-position-controller-system.so">
  	<joint_name>bl_knee_joint</joint_name>
    <use_velocity_commands>false</use_velocity_commands>
    <p_gain>5</p_gain>
    <i_gain>0.1</i_gain>
    <d_gain>0.1</d_gain>
    </plugin>
    <plugin name="gz::sim::systems::JointPositionController" filename="libgz-sim-joint-position-controller-system.so">
  	<joint_name>bl_foot_joint</joint_name>
    <use_velocity_commands>false</use_velocity_commands>
    <p_gain>5</p_gain>
    <i_gain>0.1</i_gain>
    <d_gain>0.1</d_gain>
    </plugin>
    <plugin name="gz::sim::systems::JointPositionController" filename="libgz-sim-joint-position-controller-system.so">
  	<joint_name>br_hip_joint</joint_name>
    <use_velocity_commands>false</use_velocity_commands>
    <p_gain>5</p_gain>
    <i_gain>0.1</i_gain>
    <d_gain>0.1</d_gain>
    </plugin>
    <plugin name="gz::sim::systems::JointPositionController" filename="libgz-sim-joint-position-controller-system.so">
  	<joint_name>br_knee_joint</joint_name>
    <use_velocity_commands>false</use_velocity_commands>
    <p_gain>5</p_gain>
    <i_gain>0.1</i_gain>
    <d_gain>0.1</d_gain>
    </plugin>
    <plugin name="gz::sim::systems::JointPositionController" filename="libgz-sim-joint-position-controller-system.so">
  	<joint_name>br_foot_joint</joint_name>
    <use_velocity_commands>false</use_velocity_commands>
    <p_gain>5</p_gain>
    <i_gain>0.1</i_gain>
    <d_gain>0.1</d_gain>
    </plugin>
    <plugin
    filename="gz-sim-joint-state-publisher-system"
    name="gz::sim::systems::JointStatePublisher">
    <joint_name>fr_hip_joint</joint_name>
    </plugin>
    <plugin
    filename="gz-sim-joint-state-publisher-system"
    name="gz::sim::systems::JointStatePublisher">
    <joint_name>fr_knee_joint</joint_name>
    </plugin>
    <plugin
    filename="gz-sim-joint-state-publisher-system"
    name="gz::sim::systems::JointStatePublisher">
    <joint_name>fr_foot_joint</joint_name>
    </plugin>
    <plugin
    filename="gz-sim-joint-state-publisher-system"
    name="gz::sim::systems::JointStatePublisher">
    <joint_name>br_hip_joint</joint_name>
    </plugin>
    <plugin
    filename="gz-sim-joint-state-publisher-system"
    name="gz::sim::systems::JointStatePublisher">
    <joint_name>br_knee_joint</joint_name>
    </plugin>
    <plugin
    filename="gz-sim-joint-state-publisher-system"
    name="gz::sim::systems::JointStatePublisher">
    <joint_name>br_foot_joint</joint_name>
    </plugin>
    <plugin
    filename="gz-sim-joint-state-publisher-system"
    name="gz::sim::systems::JointStatePublisher">
    <joint_name>bl_hip_joint</joint_name>
    </plugin>
    <plugin
    filename="gz-sim-joint-state-publisher-system"
    name="gz::sim::systems::JointStatePublisher">
    <joint_name>bl_knee_joint</joint_name>
    </plugin>
    <plugin
    filename="gz-sim-joint-state-publisher-system"
    name="gz::sim::systems::JointStatePublisher">
    <joint_name>bl_foot_joint</joint_name>
    </plugin>
    <plugin
    filename="gz-sim-joint-state-publisher-system"
    name="gz::sim::systems::JointStatePublisher">
    <joint_name>fl_hip_joint</joint_name>
    </plugin>
    <plugin
    filename="gz-sim-joint-state-publisher-system"
    name="gz::sim::systems::JointStatePublisher">
    <joint_name>fl_knee_joint</joint_name>
    </plugin>
    <plugin
    filename="gz-sim-joint-state-publisher-system"
    name="gz::sim::systems::JointStatePublisher">
    <joint_name>fl_foot_joint</joint_name>
    </plugin>
  </model>
</sdf>
