<sdf version='1.11'>
  <model name='THex_Quadruped'>
  <self_collide>true</self_collide>
    <link name='base_link'>
      <inertial>
        <pose>-1.0171e-10 -0.0086064999999999996 0.036080000000000001 0 0 0</pose>
        <mass>0.30423</mass>
        <inertia>
          <ixx>0.00232</ixx>
          <ixy>0</ixy>
          <ixz>0</ixz>
          <iyy>0.00064</iyy>
          <iyz>0.00008</iyz>
          <izz>0.00225</izz>
        </inertia>
      </inertial>

      <sensor name="imu_sensor" type="imu">
        <always_on>1</always_on>
        <update_rate>1000</update_rate> 
        <visualize>true</visualize>
      </sensor>

      <collision name='base_link_collision'>
        <pose>0 0 0 0 0 0</pose>
        <geometry>
          <mesh>
            <scale>1 1 1</scale>
            <uri>model://THex_Quadruped/meshes/base_link_collision.STL</uri>
          </mesh>
        </geometry>
      </collision>
      <visual name='base_link_visual'>
        <pose>0 0 0 0 0 0</pose>
        <geometry>
          <mesh>
            <scale>1 1 1</scale>
            <uri>model://THex_Quadruped/meshes/base_link.STL</uri>
          </mesh>
        </geometry>
        <material>
          <diffuse>1 1 1 1</diffuse>
          <ambient>1 1 1 1</ambient>
        </material>
      </visual>
    </link>
    <joint name='bl_hip_joint' type='revolute'>
      <pose relative_to='base_link'>-0.053162000000000001 -0.12711 0 0 0 -2.3719999999999999</pose>
      <parent>base_link</parent>
      <child>bl_hip</child>
      <axis>
        <xyz>0 0 1</xyz>
        <limit>
          <lower>-0.7853</lower>
          <upper>0.7853</upper>
          <effort>0.94140000000000001</effort>
          <velocity>5.2300000000000004</velocity>
        </limit>
        <dynamics>
          <spring_reference>0</spring_reference>
          <spring_stiffness>0</spring_stiffness>
        </dynamics>
      </axis>
      <physics>
        <provide_feedback>true</provide_feedback>
      </physics>
      <sensor name="force_torque_sensor" type="force_torque">
        <update_rate>100</update_rate>
        <always_on>true</always_on>
        <visualize>true</visualize>
        <topic>bl_hip_force_torque</topic>
        <force_torque>
          <frame>sensor</frame>
          <measure_direction>parent_to_child</measure_direction>
        </force_torque>
      </sensor>
    </joint>
    <link name='bl_hip'>
      <pose relative_to='bl_hip_joint'>0 0 0 0 0 0</pose>
      <inertial>
        <pose>0.015013 -0.0039617999999999997 0.012298999999999999 0 0 0</pose>
        <mass>0.14763</mass>
        <inertia>
          <ixx>0.00005</ixx>
          <ixy>0.00001</ixy>
          <ixz>-0.00001</ixz>
          <iyy>0.00005</iyy>
          <iyz>0</iyz>
          <izz>0.00006</izz>
        </inertia>
      </inertial>
      <collision name='bl_hip_collision'>
        <pose>0 0 0 0 0 0</pose>
        <geometry>
          <mesh>
            <scale>1 1 1</scale>
            <uri>model://THex_Quadruped/meshes/bl_hip_collision.STL</uri>
          </mesh>
        </geometry>
      </collision>
      <visual name='bl_hip_visual'>
        <pose>0 0 0 0 0 0</pose>
        <geometry>
          <mesh>
            <scale>1 1 1</scale>
            <uri>model://THex_Quadruped/meshes/bl_hip.STL</uri>
          </mesh>
        </geometry>
        <material>
          <diffuse>1 1 1 1</diffuse>
          <ambient>1 1 1 1</ambient>
        </material>
      </visual>
    </link>
    <joint name='bl_knee_joint' type='revolute'>
      <pose relative_to='bl_hip'>0.028451000000000001 0 0 -1.5602 0 -7.8500057236944626e-17</pose>
      <parent>bl_hip</parent>
      <child>bl_knee</child>
      <axis>
        <xyz>0 0 1</xyz>
        <limit>
          <lower>-1.5707</lower>
          <upper>1.5707</upper>
          <effort>0.94140000000000001</effort>
          <velocity>5.2300000000000004</velocity>
        </limit>
        <dynamics>
          <spring_reference>0</spring_reference>
          <spring_stiffness>0</spring_stiffness>
        </dynamics>
      </axis>
      <physics>
        <provide_feedback>true</provide_feedback>
      </physics>
      <sensor name="force_torque_sensor" type="force_torque">
        <update_rate>100</update_rate>
        <always_on>true</always_on>
        <visualize>true</visualize>
        <topic>bl_knee_force_torque</topic>
        <force_torque>
          <frame>sensor</frame>
          <measure_direction>parent_to_child</measure_direction>
        </force_torque>
      </sensor>
    </joint>
    <link name='bl_knee'>
      <pose relative_to='bl_knee_joint'>0 0 0 0 0 0</pose>
      <inertial>
        <pose>0.045290999999999998 0.0044812999999999997 -0.0012523 0 0 0</pose>
        <mass>0.03468</mass>
        <inertia>
          <ixx>0.00002</ixx>
          <ixy>0</ixy>
          <ixz>0</ixz>
          <iyy>0.00003</iyy>
          <iyz>0</iyz>
          <izz>0.00002</izz>
        </inertia>
      </inertial>
      <collision name='bl_knee_collision'>
        <pose>0 0 0 0 0 0</pose>
        <geometry>
          <mesh>
            <scale>1 1 1</scale>
            <uri>model://THex_Quadruped/meshes/bl_knee_collision.STL</uri>
          </mesh>
        </geometry>
      </collision>
      <visual name='bl_knee_visual'>
        <pose>0 0 0 0 0 0</pose>
        <geometry>
          <mesh>
            <scale>1 1 1</scale>
            <uri>model://THex_Quadruped/meshes/bl_knee.STL</uri>
          </mesh>
        </geometry>
        <material>
          <diffuse>1 1 1 1</diffuse>
          <ambient>1 1 1 1</ambient>
        </material>
      </visual>
    </link>
    <joint name='bl_foot_joint' type='revolute'>
      <pose relative_to='bl_knee'>0.073068999999999995 0.018655999999999999 -0.00019751 3.1339999999999999 0.0073895000000000054 0.7853</pose>
      <parent>bl_knee</parent>
      <child>bl_foot</child>
      <axis>
        <xyz>0 0 1</xyz>
        <limit>
          <lower>-1.5707</lower>
          <upper>1.5707</upper>
          <effort>0.94140000000000001</effort>
          <velocity>5.2300000000000004</velocity>
        </limit>
        <dynamics>
          <spring_reference>0</spring_reference>
          <spring_stiffness>0</spring_stiffness>
        </dynamics>
      </axis>
      <physics>
        <provide_feedback>true</provide_feedback>
      </physics>
      <sensor name="force_torque_sensor" type="force_torque">
        <update_rate>100</update_rate>
        <always_on>true</always_on>
        <visualize>true</visualize>
        <topic>bl_foot_force_torque</topic>
        <force_torque>
          <frame>sensor</frame>
          <measure_direction>parent_to_child</measure_direction>
        </force_torque>
      </sensor>
    </joint>
    <link name='bl_foot'>
      <pose relative_to='bl_foot_joint'>0 0 0 0 0 0</pose>
      <inertial>
        <pose>0.021142000000000001 0.0035788 -0.0013921000000000001 0 0 0</pose>
        <mass>0.09125</mass>
        <inertia>
          <ixx>0.00001</ixx>
          <ixy>0</ixy>
          <ixz>0</ixz>
          <iyy>0.00004</iyy>
          <iyz>0</iyz>
          <izz>0.00004</izz>
        </inertia>
      </inertial>
      <collision name='bl_foot_collision'>
        <pose>0 0 0 0 0 0</pose>
        <geometry>
          <mesh>
            <scale>1 1 1</scale>
            <uri>model://THex_Quadruped/meshes/bl_foot_collision.STL</uri>
          </mesh>
        </geometry>
      </collision>

      <sensor name="bl_contact" type="contact">
        <contact>
          <collision>bl_foot_collision</collision>
        </contact>
        <update_rate>1000</update_rate>
        <topic>/contact/bl</topic>
        <always_on>true</always_on>
      </sensor>

      <visual name='bl_foot_visual'>
        <pose>0 0 0 0 0 0</pose>
        <geometry>
          <mesh>
            <scale>1 1 1</scale>
            <uri>model://THex_Quadruped/meshes/bl_foot.STL</uri>
          </mesh>
        </geometry>
        <material>
          <diffuse>1 1 1 1</diffuse>
          <ambient>1 1 1 1</ambient>
        </material>
      </visual>
    </link>
    <joint name='br_hip_joint' type='revolute'>
      <pose relative_to='base_link'>0.053162000000000001 -0.12711 0.00053339999999999995 0 0 -0.77529000000000003</pose>
      <parent>base_link</parent>
      <child>br_hip</child>
      <axis>
        <xyz>0 0 1</xyz>
        <limit>
          <lower>-0.7853</lower>
          <upper>0.7853</upper>
          <effort>0.94140000000000001</effort>
          <velocity>5.2300000000000004</velocity>
        </limit>
        <dynamics>
          <spring_reference>0</spring_reference>
          <spring_stiffness>0</spring_stiffness>
        </dynamics>
      </axis>
      <physics>
        <provide_feedback>true</provide_feedback>
      </physics>
      <sensor name="force_torque_sensor" type="force_torque">
        <update_rate>100</update_rate>
        <always_on>true</always_on>
        <visualize>true</visualize>
        <topic>br_hip_force_torque</topic>
        <force_torque>
          <frame>sensor</frame>
          <measure_direction>parent_to_child</measure_direction>
        </force_torque>
      </sensor>
    </joint>
    <link name='br_hip'>
      <pose relative_to='br_hip_joint'>0 0 0 0 0 0</pose>
      <inertial>
        <pose>0.014987 0.0036917999999999999 0.011971000000000001 0 0 0</pose>
        <mass>0.14763</mass>
        <inertia>
          <ixx>0.00005</ixx>
          <ixy>-0.00001</ixy>
          <ixz>-0.00001</ixz>
          <iyy>0.00005</iyy>
          <iyz>0</iyz>
          <izz>0.00006</izz>
        </inertia>
      </inertial>
      <collision name='br_hip_collision'>
        <pose>0 0 0 0 0 0</pose>
        <geometry>
          <mesh>
            <scale>1 1 1</scale>
            <uri>model://THex_Quadruped/meshes/br_hip_collision.STL</uri>
          </mesh>
        </geometry>
      </collision>
      <visual name='br_hip_visual'>
        <pose>0 0 0 0 0 0</pose>
        <geometry>
          <mesh>
            <scale>1 1 1</scale>
            <uri>model://THex_Quadruped/meshes/br_hip.STL</uri>
          </mesh>
        </geometry>
        <material>
          <diffuse>1 1 1 1</diffuse>
          <ambient>1 1 1 1</ambient>
        </material>
      </visual>
    </link>
    <joint name='br_knee_joint' type='revolute'>
      <pose relative_to='br_hip'>0.028448999999999999 0 0 1.5643 0 0</pose>
      <parent>br_hip</parent>
      <child>br_knee</child>
      <axis>
        <xyz>0 0 1</xyz>
        <limit>
          <lower>-1.5707</lower>
          <upper>1.5707</upper>
          <effort>0.94140000000000001</effort>
          <velocity>5.2300000000000004</velocity>
        </limit>
        <dynamics>
          <spring_reference>0</spring_reference>
          <spring_stiffness>0</spring_stiffness>
        </dynamics>
      </axis>
      <physics>
        <provide_feedback>true</provide_feedback>
      </physics>
      <sensor name="force_torque_sensor" type="force_torque">
        <update_rate>100</update_rate>
        <always_on>true</always_on>
        <visualize>true</visualize>
        <topic>br_knee_force_torque</topic>
        <force_torque>
          <frame>sensor</frame>
          <measure_direction>parent_to_child</measure_direction>
        </force_torque>
      </sensor>
    </joint>
    <link name='br_knee'>
      <pose relative_to='br_knee_joint'>0 0 0 0 0 0</pose>
      <inertial>
        <pose>0.045282999999999997 -0.0044812999999999997 -0.0010646 0 0 0</pose>
        <mass>0.03468</mass>
        <inertia>
          <ixx>0.00002</ixx>
          <ixy>0</ixy>
          <ixz>0</ixz>
          <iyy>0.00003</iyy>
          <iyz>0</iyz>
          <izz>0.00002</izz>
        </inertia>
      </inertial>
      <collision name='br_knee_collision'>
        <pose>0 0 0 0 0 0</pose>
        <geometry>
          <mesh>
            <scale>1 1 1</scale>
            <uri>model://THex_Quadruped/meshes/br_knee_collision.STL</uri>
          </mesh>
        </geometry>
      </collision>
      <visual name='br_knee_visual'>
        <pose>0 0 0 0 0 0</pose>
        <geometry>
          <mesh>
            <scale>1 1 1</scale>
            <uri>model://THex_Quadruped/meshes/br_knee.STL</uri>
          </mesh>
        </geometry>
        <material>
          <diffuse>1 1 1 1</diffuse>
          <ambient>1 1 1 1</ambient>
        </material>
      </visual>
    </link>
    <joint name='br_foot_joint' type='revolute'>
      <pose relative_to='br_knee'>0.073065000000000005 -0.018655999999999999 -0.00012210000000000001 -3.1368999999999998 0.0045678000000000021 -0.7853</pose>
      <parent>br_knee</parent>
      <child>br_foot</child>
      <axis>
        <xyz>0 0 1</xyz>
        <limit>
          <lower>-1.5707</lower>
          <upper>1.5707</upper>
          <effort>0.94140000000000001</effort>
          <velocity>5.2300000000000004</velocity>
        </limit>
        <dynamics>
          <spring_reference>0</spring_reference>
          <spring_stiffness>0</spring_stiffness>
        </dynamics>
      </axis>
      <physics>
        <provide_feedback>true</provide_feedback>
      </physics>
      <sensor name="force_torque_sensor" type="force_torque">
        <update_rate>100</update_rate>
        <always_on>true</always_on>
        <visualize>true</visualize>
        <topic>br_foot_force_torque</topic>
        <force_torque>
          <frame>sensor</frame>
          <measure_direction>parent_to_child</measure_direction>
        </force_torque>
      </sensor>
    </joint>
    <link name='br_foot'>
      <pose relative_to='br_foot_joint'>0 0 0 0 0 0</pose>
      <inertial>
        <pose>0.020857000000000001 -0.003581 -0.0013921000000000001 0 0 0</pose>
        <mass>0.09125</mass>
        <inertia>
          <ixx>0.00001</ixx>
          <ixy>0</ixy>
          <ixz>0</ixz>
          <iyy>0.00004</iyy>
          <iyz>0</iyz>
          <izz>0.00004</izz>
        </inertia>
      </inertial>
      <collision name='br_foot_collision'>
        <pose>0 0 0 0 0 0</pose>
        <geometry>
          <mesh>
            <scale>1 1 1</scale>
            <uri>model://THex_Quadruped/meshes/br_foot_collision.STL</uri>
          </mesh>
        </geometry>
      </collision>

      <sensor name="br_contact" type="contact">
        <contact>
          <collision>br_foot_collision</collision>
        </contact>
        <update_rate>1000</update_rate>
        <topic>/contact/br</topic>
        <always_on>true</always_on>
      </sensor>

      <visual name='br_foot_visual'>
        <pose>0 0 0 0 0 0</pose>
        <geometry>
          <mesh>
            <scale>1 1 1</scale>
            <uri>model://THex_Quadruped/meshes/br_foot.STL</uri>
          </mesh>
        </geometry>
        <material>
          <diffuse>1 1 1 1</diffuse>
          <ambient>1 1 1 1</ambient>
        </material>
      </visual>
    </link>
    <joint name='fl_hip_joint' type='revolute'>
      <pose relative_to='base_link'>-0.059512000000000002 0.078853999999999994 0 0 0 2.3666</pose>
      <parent>base_link</parent>
      <child>fl_hip</child>
      <axis>
        <xyz>0 0 1</xyz>
        <limit>
          <lower>-0.7853</lower>
          <upper>0.7853</upper>
          <effort>0.94140000000000001</effort>
          <velocity>5.2300000000000004</velocity>
        </limit>
        <dynamics>
          <spring_reference>0</spring_reference>
          <spring_stiffness>0</spring_stiffness>
        </dynamics>
      </axis>
      <physics>
        <provide_feedback>true</provide_feedback>
      </physics>
      <sensor name="force_torque_sensor" type="force_torque">
        <update_rate>100</update_rate>
        <always_on>true</always_on>
        <visualize>true</visualize>
        <topic>fl_hip_force_torque</topic>
        <force_torque>
          <frame>sensor</frame>
          <measure_direction>parent_to_child</measure_direction>
        </force_torque>
      </sensor>
    </joint>
    <link name='fl_hip'>
      <pose relative_to='fl_hip_joint'>0 0 0 0 0 0</pose>
      <inertial>
        <pose>0.015006 0.0056423000000000003 0.012298999999999999 0 0 0</pose>
        <mass>0.14763</mass>
        <inertia>
          <ixx>0.00005</ixx>
          <ixy>-0.00001</ixy>
          <ixz>-0.00001</ixz>
          <iyy>0.00005</iyy>
          <iyz>0</iyz>
          <izz>0.00006</izz>
        </inertia>
      </inertial>
      <collision name='fl_hip_collision'>
        <pose>0 0 0 0 0 0</pose>
        <geometry>
          <mesh>
            <scale>1 1 1</scale>
            <uri>model://THex_Quadruped/meshes/fl_hip_collision.STL</uri>
          </mesh>
        </geometry>
      </collision>
      <visual name='fl_hip_visual'>
        <pose>0 0 0 0 0 0</pose>
        <geometry>
          <mesh>
            <scale>1 1 1</scale>
            <uri>model://THex_Quadruped/meshes/fl_hip.STL</uri>
          </mesh>
        </geometry>
        <material>
          <diffuse>1 1 1 1</diffuse>
          <ambient>1 1 1 1</ambient>
        </material>
      </visual>
    </link>
    <joint name='fl_knee_joint' type='revolute'>
      <pose relative_to='fl_hip'>0.028448999999999999 0 0 -1.5774999999999999 0 -7.8503197062369069e-17</pose>
      <parent>fl_hip</parent>
      <child>fl_knee</child>
      <axis>
        <xyz>0 0 1</xyz>
        <limit>
          <lower>-1.5707</lower>
          <upper>1.5707</upper>
          <effort>0.94140000000000001</effort>
          <velocity>5.2300000000000004</velocity>
        </limit>
        <dynamics>
          <spring_reference>0</spring_reference>
          <spring_stiffness>0</spring_stiffness>
        </dynamics>
      </axis>
      <physics>
        <provide_feedback>true</provide_feedback>
      </physics>
      <sensor name="force_torque_sensor" type="force_torque">
        <update_rate>100</update_rate>
        <always_on>true</always_on>
        <visualize>true</visualize>
        <topic>fl_knee_force_torque</topic>
        <force_torque>
          <frame>sensor</frame>
          <measure_direction>parent_to_child</measure_direction>
        </force_torque>
      </sensor>
    </joint>
    <link name='fl_knee'>
      <pose relative_to='fl_knee_joint'>0 0 0 0 0 0</pose>
      <inertial>
        <pose>0.045273000000000001 0.0044812999999999997 -0.00044768999999999999 0 0 0</pose>
        <mass>0.034680999999999997</mass>
        <inertia>
          <ixx>0.00002</ixx>
          <ixy>0</ixy>
          <ixz>0</ixz>
          <iyy>0.00003</iyy>
          <iyz>0</iyz>
          <izz>0.00002</izz>
        </inertia>
      </inertial>
      <collision name='fl_knee_collision'>
        <pose>0 0 0 0 0 0</pose>
        <geometry>
          <mesh>
            <scale>1 1 1</scale>
            <uri>model://THex_Quadruped/meshes/fl_knee_collision.STL</uri>
          </mesh>
        </geometry>
      </collision>
      <visual name='fl_knee_visual'>
        <pose>0 0 0 0 0 0</pose>
        <geometry>
          <mesh>
            <scale>1 1 1</scale>
            <uri>model://THex_Quadruped/meshes/fl_knee.STL</uri>
          </mesh>
        </geometry>
        <material>
          <diffuse>1 1 1 1</diffuse>
          <ambient>1 1 1 1</ambient>
        </material>
      </visual>
    </link>
    <joint name='fl_foot_joint' type='revolute'>
      <pose relative_to='fl_knee'>0.073066000000000006 0.018655999999999999 0.00012569 -3.1368 -0.0047025000000000001 0.7853</pose>
      <parent>fl_knee</parent>
      <child>fl_foot</child>
      <axis>
        <xyz>0 0 1</xyz>
        <limit>
          <lower>-1.5707</lower>
          <upper>1.5707</upper>
          <effort>0.94140000000000001</effort>
          <velocity>5.2300000000000004</velocity>
        </limit>
        <dynamics>
          <spring_reference>0</spring_reference>
          <spring_stiffness>0</spring_stiffness>
        </dynamics>
      </axis>
      <physics>
        <provide_feedback>true</provide_feedback>
      </physics>
      <sensor name="force_torque_sensor" type="force_torque">
        <update_rate>100</update_rate>
        <always_on>true</always_on>
        <visualize>true</visualize>
        <topic>fl_foot_force_torque</topic>
        <force_torque>
          <frame>sensor</frame>
          <measure_direction>parent_to_child</measure_direction>
        </force_torque>
      </sensor>
    </joint>
    <link name='fl_foot'>
      <pose relative_to='fl_foot_joint'>0 0 0 0 0 0</pose>
      <inertial>
        <pose>0.021142000000000001 0.0035788 -0.0013921000000000001 0 0 0</pose>
        <mass>0.09125</mass>
        <inertia>
          <ixx>0.00001</ixx>
          <ixy>0</ixy>
          <ixz>0</ixz>
          <iyy>0.00004</iyy>
          <iyz>0</iyz>
          <izz>0.00004</izz>
        </inertia>
      </inertial>
      <collision name='fl_foot_collision'>
        <pose>0 0 0 0 0 0</pose>
        <geometry>
          <mesh>
            <scale>1 1 1</scale>
            <uri>model://THex_Quadruped/meshes/fl_foot_collision.STL</uri>
          </mesh>
        </geometry>
      </collision>

      <sensor name="fl_contact" type="contact">
        <contact>
          <collision>fl_foot_collision</collision>
        </contact>
        <update_rate>1000</update_rate>
        <topic>/contact/fl</topic>
        <always_on>true</always_on>
      </sensor>

      <visual name='fl_foot_visual'>
        <pose>0 0 0 0 0 0</pose>
        <geometry>
          <mesh>
            <scale>1 1 1</scale>
            <uri>model://THex_Quadruped/meshes/fl_foot.STL</uri>
          </mesh>
        </geometry>
        <material>
          <diffuse>1 1 1 1</diffuse>
          <ambient>1 1 1 1</ambient>
        </material>
      </visual>
    </link>
    <joint name='fr_hip_joint' type='revolute'>
      <pose relative_to='base_link'>0.059512000000000002 0.078853999999999994 0.00053339999999999995 0 0 0.76931000000000005</pose>
      <parent>base_link</parent>
      <child>fr_hip</child>
      <axis>
        <xyz>0 0 1</xyz>
        <limit>
          <lower>-0.7853</lower>
          <upper>0.7853</upper>
          <effort>0.94140000000000001</effort>
          <velocity>5.2300000000000004</velocity>
        </limit>
        <dynamics>
          <spring_reference>0</spring_reference>
          <spring_stiffness>0</spring_stiffness>
        </dynamics>
      </axis>
      <physics>
        <provide_feedback>true</provide_feedback>
      </physics>
      <sensor name="force_torque_sensor" type="force_torque">
        <update_rate>100</update_rate>
        <always_on>true</always_on>
        <visualize>true</visualize>
        <topic>fr_hip_force_torque</topic>
        <force_torque>
          <frame>sensor</frame>
          <measure_direction>parent_to_child</measure_direction>
        </force_torque>
      </sensor>
    </joint>
    <link name='fr_hip'>
      <pose relative_to='fr_hip_joint'>0 0 0 0 0 0</pose>
      <inertial>
        <pose>0.015044 -0.0059121 0.011971000000000001 0 0 0</pose>
        <mass>0.14763</mass>
        <inertia>
          <ixx>0.00005</ixx>
          <ixy>0.00001</ixy>
          <ixz>-0.00001</ixz>
          <iyy>0.00005</iyy>
          <iyz>0</iyz>
          <izz>0.00006</izz>
        </inertia>
      </inertial>
      <collision name='fr_hip_collision'>
        <pose>0 0 0 0 0 0</pose>
        <geometry>
          <mesh>
            <scale>1 1 1</scale>
            <uri>model://THex_Quadruped/meshes/fr_hip_collision.STL</uri>
          </mesh>
        </geometry>
      </collision>
      <visual name='fr_hip_visual'>
        <pose>0 0 0 0 0 0</pose>
        <geometry>
          <mesh>
            <scale>1 1 1</scale>
            <uri>model://THex_Quadruped/meshes/fr_hip.STL</uri>
          </mesh>
        </geometry>
        <material>
          <diffuse>1 1 1 1</diffuse>
          <ambient>1 1 1 1</ambient>
        </material>
      </visual>
    </link>
    <joint name='fr_knee_joint' type='revolute'>
      <pose relative_to='fr_hip'>0.028451000000000001 0 0 1.5816000000000001 0 0</pose>
      <parent>fr_hip</parent>
      <child>fr_knee</child>
      <axis>
        <xyz>0 0 1</xyz>
        <limit>
          <lower>-1.5707</lower>
          <upper>1.5707</upper>
          <effort>0.94140000000000001</effort>
          <velocity>5.2300000000000004</velocity>
        </limit>
        <dynamics>
          <spring_reference>0</spring_reference>
          <spring_stiffness>0</spring_stiffness>
        </dynamics>
      </axis>
      <physics>
        <provide_feedback>true</provide_feedback>
      </physics>
      <sensor name="force_torque_sensor" type="force_torque">
        <update_rate>100</update_rate>
        <always_on>true</always_on>
        <visualize>true</visualize>
        <topic>fr_knee_force_torque</topic>
        <force_torque>
          <frame>sensor</frame>
          <measure_direction>parent_to_child</measure_direction>
        </force_torque>
      </sensor>
    </joint>
    <link name='fr_knee'>
      <pose relative_to='fr_knee_joint'>0 0 0 0 0 0</pose>
      <inertial>
        <pose>0.045275000000000003 -0.0044812999999999997 -0.00025994000000000001 0 0 0</pose>
        <mass>0.03468</mass>
        <inertia>
          <ixx>0.00002</ixx>
          <ixy>0</ixy>
          <ixz>0</ixz>
          <iyy>0.00003</iyy>
          <iyz>0</iyz>
          <izz>0.00002</izz>
        </inertia>
      </inertial>
      <collision name='fr_knee_collision'>
        <pose>0 0 0 0 0 0</pose>
        <geometry>
          <mesh>
            <scale>1 1 1</scale>
            <uri>model://THex_Quadruped/meshes/fr_knee_collision.STL</uri>
          </mesh>
        </geometry>
      </collision>
      <visual name='fr_knee_visual'>
        <pose>0 0 0 0 0 0</pose>
        <geometry>
          <mesh>
            <scale>1 1 1</scale>
            <uri>model://THex_Quadruped/meshes/fr_knee.STL</uri>
          </mesh>
        </geometry>
        <material>
          <diffuse>1 1 1 1</diffuse>
          <ambient>1 1 1 1</ambient>
        </material>
      </visual>
    </link>
    <joint name='fr_foot_joint' type='revolute'>
      <pose relative_to='fr_knee'>0.073069999999999996 -0.018655999999999999 0.00020110000000000001 3.1339000000000001 -0.0075232000000000007 -0.7853</pose>
      <parent>fr_knee</parent>
      <child>fr_foot</child>
      <axis>
        <xyz>0 0 1</xyz>
        <limit>
          <lower>-1.5707</lower>
          <upper>1.5707</upper>
          <effort>0.94140000000000001</effort>
          <velocity>5.2300000000000004</velocity>
        </limit>
        <dynamics>
          <spring_reference>0</spring_reference>
          <spring_stiffness>0</spring_stiffness>
        </dynamics>
      </axis>
      <physics>
        <provide_feedback>true</provide_feedback>
      </physics>
      <sensor name="force_torque_sensor" type="force_torque">
        <update_rate>100</update_rate>
        <always_on>true</always_on>
        <visualize>true</visualize>
        <topic>fr_foot_force_torque</topic>
        <force_torque>
          <frame>sensor</frame>
          <measure_direction>parent_to_child</measure_direction>
        </force_torque>
      </sensor>
    </joint>
    <link name='fr_foot'>
      <pose relative_to='fr_foot_joint'>0 0 0 0 0 0</pose>
      <inertial>
        <pose>0.020857000000000001 -0.003581 -0.0013921000000000001 0 0 0</pose>
        <mass>0.09125</mass>
        <inertia>
          <ixx>0.00001</ixx>
          <ixy>0</ixy>
          <ixz>0</ixz>
          <iyy>0.00004</iyy>
          <iyz>0</iyz>
          <izz>0.00004</izz>
        </inertia>
      </inertial>
      <collision name='fr_foot_collision'>
        <pose>0.09 0 0 0 0 0</pose>
        <geometry>
          <mesh>
            <scale>1 1 1</scale>
            <uri>model://THex_Quadruped/meshes/fr_foot_collision.STL</uri>
          </mesh>
        </geometry>
      </collision>

      <sensor name="fr_contact" type="contact">
        <contact>
          <collision>fr_foot_collision</collision>
        </contact>
        <update_rate>1000</update_rate>
        <topic>/contact/fr</topic>
        <always_on>true</always_on>
      </sensor>

      <visual name='fr_foot_visual'>
        <pose>0 0 0 0 0 0</pose>
        <geometry>
          <mesh>
            <scale>1 1 1</scale>
            <uri>model://THex_Quadruped/meshes/fr_foot.STL</uri>
          </mesh>
        </geometry>
        <material>
          <diffuse>1 1 1 1</diffuse>
          <ambient>1 1 1 1</ambient>
        </material>
      </visual>
    </link>
    <plugin filename="gz_ros2_control-system" name="gz_ros2_control::GazeboSimROS2ControlPlugin">
      <parameters>/workspaces/FYP-Legged-Robot/Code/ROS/src/cheetah_ros2/config/cheetah_controllers.yaml</parameters>
    </plugin>
    <plugin
        filename="gz-sim-odometry-publisher-system"
        name="gz::sim::systems::OdometryPublisher">
        <odom_frame>odom</odom_frame>
        <robot_base_frame>base_link</robot_base_frame>
    </plugin>
  </model>
</sdf>
